Workbook

Sheet Overview
A1: Month | B1: Earning | C1: Total Spend | D1: Net Profit | H1: Feb | I1: Mar | J1: Apr | K1: May | L1: Jun | M1: Jul | N1: Aug | O1: Sep | P1: Oct | Q1: Nov | R1: Dec | S1: Total
A2: Feb | B2: =Feb!B33 -> 5001.5 | C2: =Feb!W33 -> 3261.78 | D2: =B2-C2 -> 1739.72 | G2: Insuran | H2: =Feb!C33 -> 128 | I2: =March!C34 -> 0 | J2: =April!C34 -> 196 | K2: =May!C34 -> 217 | L2: =June!C34 -> 210 | M2: =July!C34 -> 210 | N2: =Aug!C34 -> 217 | O2: =Sep!C34 -> 210 | P2: =Oct!C34 -> 210 | Q2: =Nov!C34 -> 70 | R2: =Dec!C34 -> 0 | S2: =SUM(H2:R2) -> 1668
A3: Mar | B3: =March!B34 -> 0 | C3: =March!W34 -> 1873.06 | D3: =B3-C3 -> -1873.06 | G3: Minyak | H3: =Feb!D33 -> 1188 | I3: =March!D34 -> 60 | J3: =April!D35 -> 1993 | K3: =May!D35 -> 2160 | L3: =June!D35 -> 1974 | M3: =July!D35 -> 2118 | N3: =Aug!D35 -> 1959 | O3: =Sep!D35 -> 1698 | P3: =Oct!D35 -> 2380 | Q3: =Nov!D35 -> 600 | R3: =Dec!D35 -> 0 | S3: =SUM(H3:R3) -> 16130
A4: Apr | B4: =April!B34 -> 9272.02 | C4: =April!AG34 -> 3280.65 | D4: =B4-C4 -> 5991.37 | G4: Makan | H4: =Feb!F34 -> 438.05 | I4: =March!E34 -> 0 | J4: =April!F35 -> 487.2 | K4: =May!F35 -> 728.9 | L4: =June!F35 -> 691.05 | M4: =July!F35 -> 665.92 | N4: =Aug!F35 -> 658.35 | O4: =Sep!F35 -> 826.2 | P4: =Oct!F35 -> 799.85 | Q4: =Nov!F35 -> 486.45 | R4: =Dec!F35 -> 165.55 | S4: =SUM(H4:R4) -> 5947.52
A5: May | B5: =May!B34 -> 9514.47 | C5: =May!X34 -> 4293.84 | D5: =B5-C5 -> 5220.63 | G5: Oil Filter | H5: =Feb!H33 -> 440 | I5: =March!H34 -> 0 | J5: =April!H34 -> 0 | K5: =May!H34 -> 220 | L5: =June!H34 -> 220 | M5: =July!H34 -> 0 | N5: =Aug!H34 -> 220 | O5: =Sep!H34 -> 0 | P5: =Oct!H34 -> 440 | Q5: =Nov!H34 -> 220 | R5: =Dec!H34 -> 0 | S5: =SUM(H5:R5) -> 1760
A6: Jun | B6: =June!B34 -> 10166.5 | C6: =June!X34 -> 4915.75 | D6: =B6-C6 -> 5250.75 | G6: TnG | H6: =Feb!I33 -> 124.08 | I6: =March!I34 -> 0 | J6: =April!I34 -> 84.58 | K6: =May!I34 -> 147.42 | L6: =June!I34 -> 109.97 | M6: =July!I34 -> 156.63 | N6: =Aug!I34 -> 99.48 | O6: =Sep!I34 -> 135.25 | P6: =Oct!I34 -> 139.65 | Q6: =Nov!I34 -> 102.24 | R6: =Dec!I34 -> 18.6 | S6: =SUM(H6:R6) -> 1117.9
A7: Jul | B7: =July!B34 -> 9855.28 | C7: =July!X34 -> 4279.15 | D7: =B7-C7 -> 5576.13 | G7: Maintenance | H7: =Feb!J33 -> 0 | I7: =March!J34 -> 0 | J7: =April!J34 -> 0 | K7: =May!J34 -> 0 | L7: =June!J34 -> 760 | M7: =July!J34 -> 175 | N7: =Aug!J34 -> 310 | O7: =Sep!J34 -> 0 | P7: =Oct!J34 -> 416 | Q7: =Nov!J34 -> 0 | R7: =Dec!J34 -> 34 | S7: =SUM(H7:R7) -> 1695
A8: Aug | B8: =Aug!B34 -> 9901.51 | C8: =Aug!X34 -> 4896.28 | D8: =B8-C8 -> 5005.23 | G8: Grocery | H8: =Feb!K33 -> 146.7 | I8: =March!K34 -> 155.15 | J8: =April!K34 -> 86.4 | K8: =May!K34 -> 138.05 | L8: =June!K34 -> 233.2 | M8: =July!K34 -> 119.7 | N8: =Aug!K34 -> 100.65 | O8: =Sep!K34 -> 165.33 | P8: =Oct!K34 -> 419.59 | Q8: =Nov!K34 -> 366.33 | R8: =Dec!K34 -> 304.95 | S8: =SUM(H8:R8) -> 2236.05
A9: Sep | B9: =Sep!B34 -> 9215.91 | C9: =Sep!X34 -> 8886.69 | D9: =B9-C9 -> 329.22 | G9: Online Shop | H9: =Feb!L33 -> 70.19 | I9: =March!L34 -> 546.29 | J9: =April!L34 -> 5.7 | K9: =May!L34 -> 0 | L9: =June!L34 -> 21.53 | M9: =July!L34 -> 0 | N9: =Aug!L34 -> 0 | O9: =Sep!L34 -> 0 | P9: =Oct!L34 -> 0 | Q9: =Nov!L34 -> 985.2 | R9: =Dec!L34 -> 212.26 | S9: =SUM(H9:R9) -> 1841.17
A10: Oct | B10: =Oct!B34 -> 10703.39 | C10: =Oct!X34 -> 5543.47 | D10: =B10-C10 -> 5159.92 | G10: Hair Cut | H10: =Feb!M33 -> 0 | I10: =March!M34 -> 0 | J10: =April!M34 -> 0 | K10: =May!M34 -> 0 | L10: =June!M34 -> 0 | M10: =July!M34 -> 0 | N10: =Aug!M34 -> 0 | O10: =Sep!M34 -> 0 | P10: =Oct!M34 -> 0 | Q10: =Nov!M34 -> 0 | R10: =Dec!M34 -> 0 | S10: =SUM(H10:R10) -> 0
A11: Nov | B11: =Nov!B34 -> 3458.6 | C11: =Nov!X34 -> 3654.42 | D11: =B11-C11 -> -195.82 | G11: Subscription | H11: =Feb!N33 -> 52.2 | I11: =March!N34 -> 751.62 | J11: =April!N34 -> 25.9 | K11: =May!N34 -> 30 | L11: =June!N34 -> 35 | M11: =July!N34 -> 15.9 | N11: =Aug!N34 -> 15.9 | O11: =Sep!N34 -> 0 | P11: =Oct!N34 -> 0 | Q11: =Nov!N34 -> 0 | R11: =Dec!N34 -> 21.4 | S11: =SUM(H11:R11) -> 947.92
A12: Dec | B12: =Dec!B34 -> 0 | C12: =Dec!X34 -> 1325.27 | D12: =B12-C12 -> -1325.27 | G12: Charity | H12: =Feb!O33 -> 20 | I12: =March!O34 -> 10 | J12: =April!O34 -> 2.7 | K12: =May!O34 -> 18.9 | L12: =June!O34 -> 11.2 | M12: =July!O34 -> 203 | N12: =Aug!O34 -> 16 | O12: =Sep!O34 -> 10 | P12: =Oct!O34 -> 39 | Q12: =Nov!O34 -> 7 | R12: =Dec!O34 -> 0 | S12: =SUM(H12:R12) -> 337.8
A13: Total | B13: =SUM(B2:B12) -> 77089.18 | C13: =SUM(C2:C12) -> 46210.36 | G13: Phone Bil | H13: =Feb!P33 -> 70 | I13: =March!P34 -> 0 | J13: =April!P34 -> 25 | K13: =May!P34 -> 5 | L13: =June!P34 -> 0 | M13: =July!P34 -> 36 | N13: =Aug!P34 -> 50 | O13: =Sep!P34 -> 50 | P13: =Oct!P34 -> 90 | Q13: =Nov!P34 -> 10 | R13: =Dec!P34 -> 40 | S13: =SUM(H13:R13) -> 376
A14: Total | D14: =SUM(D2:D12) -> 30878.82 | G14: Laundry | H14: =Feb!Q33 -> 11 | I14: =March!Q34 -> 0 | J14: =April!Q34 -> 11 | K14: =May!Q34 -> 27 | L14: =June!Q34 -> 12 | M14: =July!Q34 -> 11 | N14: =Aug!Q34 -> 12 | O14: =Sep!Q34 -> 12 | P14: =Oct!Q34 -> 0 | Q14: =Nov!Q34 -> 0 | R14: =Dec!Q34 -> 0 | S14: =SUM(H14:R14) -> 96
G15: Rent | H15: =Feb!R33 -> 350 | I15: =March!R34 -> 350 | J15: =April!R34 -> 350 | K15: =May!R34 -> 350 | L15: =June!R34 -> 350 | M15: =July!R34 -> 350 | N15: =Aug!R34 -> 350 | O15: =Sep!R34 -> 350 | P15: =Oct!R34 -> 350 | Q15: =Nov!R34 -> 350 | R15: =Dec!R34 -> 350 | S15: =SUM(H15:R15) -> 3850
A16: Days: | B16: =counta(April!B2:B31,May!B2:B32,June!B2:B31,July!B2:B32,Aug!B2:B32,Sep!B2:B31,Oct!B2:B32,Nov!B2:B31,Dec!B2:B31) -> 222 | D16: Day (200) | E16: =counta(April!B2:B31,May!B2:B32,June!B2:B31,July!B2:B32,Aug!B2:B32,Sep!B2:B31,Oct!B2:B32,Nov!B2:B31,Dec!B2:B31)-200 -> 22 | G16: Bil E&W | H16: =Feb!S33 -> 8.56 | I16: =March!S34 -> 0 | J16: =April!S34 -> 13.17 | K16: =May!S34 -> 12.57 | L16: =June!S34 -> 0 | M16: =July!S34 -> 13 | N16: =Aug!S34 -> 12.24 | O16: =Sep!S34 -> 11.51 | P16: =Oct!S34 -> 9.38 | Q16: =Nov!S34 -> 10 | R16: =Dec!S34 -> 38.35 | S16: =SUM(H16:R16) -> 128.78
A17: Total Job | B17: =sum(J20:R20) -> 5146 | G17: Parent | H17: =Feb!T33 -> 200 | I17: =March!T34 -> 0 | J17: =April!T34 -> 0 | K17: =May!T34 -> 200 | L17: =June!T34 -> 200 | M17: =July!T34 -> 200 | N17: =Aug!T34 -> 200 | O17: =Sep!T34 -> 200 | P17: =Oct!T34 -> 200 | Q17: =Nov!T34 -> 200 | R17: =Dec!T34 -> 0 | S17: =SUM(H17:R17) -> 1600
A18: Program 200 Days | G18: Other | H18: =Feb!U33 -> 15 | I18: =March!U34 -> 0 | J18: =April!U34 -> 0 | K18: =June!U34 -> 62.8 | L18: =June!U34 -> 62.8 | M18: =July!U34 -> 5 | N18: =Aug!U34 -> 675.66 | O18: =Sep!U34 -> 5218.4 | P18: =Oct!U34 -> 50 | Q18: =Nov!U34 -> 247.2 | R18: =Dec!U34 -> 140.16 | S18: =SUM(H18:R18) -> 6477.02
A19: 1st 100 day | B19: =sum(April!AJ4:AJ31,May!AA2:AA32,June!AA2:AA31,July!AA2:AA12) -> 17452.49 | C19: Day 100 Job | D19: =sum(April!V2:V31,May!V2:V32,June!V2:V31,July!V2:V12) -> 2353 | G19: Total | H19: =SUM(H2:H18) -> 3261.78 | I19: =SUM(I2:I18) -> 1873.06 | J19: =SUM(J2:J18) -> 3280.65 | K19: =SUM(K2:K18) -> 4317.64 | L19: =SUM(L2:L18) -> 4890.75 | M19: =SUM(M2:M18) -> 4279.15 | N19: =SUM(N2:N18) -> 4896.28 | O19: =SUM(O2:O18) -> 8886.69 | ... S19: =SUM(S2:S18) -> 46209.16
A20: 2nd 100 day | B20: =sum(July!AA13:AA32,Aug!AA2:AA32,Sep!AA2:AA31,Oct!AA2:AA20) -> 12089.97 | C20: Day 100 Job | D20: =sum(July!V13:V32,Aug!V2:V32,Sep!V2:V31,Oct!V2:V20) -> 2268 | G20: Job | J20: =sum(April!V2:V31) -> 683 | K20: =sum(May!V2:V32) -> 764 | L20: =sum(June!V2:V31) -> 680 | M20: =sum(July!V2:V32) -> 717 | N20: =sum(Aug!V2:V32) -> 708 | O20: =sum(Sep!V2:V31) -> 629 | P20: =sum(Oct!V2:V32) -> 735 | Q20: =sum(Nov!V2:V31) -> 230 | R20: =sum(Dec!V2:V31) -> 0
A21: Total 200 Day | B21: =SUM(B19:B20) -> 29542.46 | C21: Day 200 Job | D21: =SUM(D19:D20) -> 4621
A22: After 2325 job maintain 5 ⭐ , finally got 1 ⭐ rating from pessenger and it's became 4.96 ⭐ which is day 100 working, maybe because from his lost item (cap) 🧢 but the cap not found in any place inside car, job is from pavi hotel to masjid negara.
A23: After 22 Day | B23: =sum(Oct!AA21:AA32,Nov!AA2:AA11) -> 5003.34 | C23: Day 222 Job | D23: =sum(April!V4:V31,May!V2:V32,June!V2:V31,July!V2:V32,Aug!V2:V32,Sep!V2:V31,Oct!V2:V32,Nov!V2:V11) -> 5146 | G23: Deposit | H23: =sum(Feb!AB2:AB29,April!AM2:AM31,May!AD2:AD32,June!AD2:AD31,July!AD2:AD32,Aug!AD2:AD32,Sep!AD2:AD31,Oct!AD2:AD32,Nov!AD2:AD31,Dec!AD2:AD31) -> 37030
A24: Total 222 Day | B24: =sum(B21:B23) -> 34545.8 | C24: Job Daily Avg. | D24: =D23/222 -> 23.18018
A25: Myvi Repair | B25: =3000+1865 -> 4865
A26: If no Repair | B26: =sum(B24:B25) -> 39410.8
A27: 3 April - 19 October 2025 : 200 Days | D27: 3 April - 10 November 2025 : 222 Days | H27: =CONCATENATE("Total job for 222 days is"," ",D23," ","Jobs") -> Total job for 222 days is 5146 Jobs

Sheet Feb
A1: Date | B1: Earning | C1: Insuran | D1: Minyak | F1: Makan | H1: Oil Filter | I1: TnG | J1: Maintenance | K1: Grocery | L1: Online Shop | M1: Hair Cut | N1: Subscription | O1: Charity | P1: Phone Bil | Q1: Laundry | R1: Rent | S1: Bil E&W | T1: Parent | U1: Other | V1: Remarks | W1: Total Spend | X1: Weekly Earning | Y1: Weekly Spend | Z1: Net Daily | AA1: Net Weekly | AB1: Deposit
A2: 45689 | F2: 15.5 | K2: 7 | P2: 30 | R2: 350 | V2: ubat demam, maxis | W2: =SUM(C2:V2) -> 402.5 | Z2: =B2-W2 -> -402.5
A3: 45690 | B3: 316.8 | C3: 5 | D3: 60 | F3: 14.5 | K3: 3.3 | O3: 12 | W3: =SUM(C3:T3) -> 94.8 | X3: =B2+B3 -> 316.8 | Y3: =sum(C2:T3) -> 497.3 | Z3: =B3-W3 -> 222 | AA3: =X3-Y3 -> -180.5
A4: 45691 | B4: 417.8 | C4: 5 | D4: 60 | F4: 12 | K4: 6.2 | W4: =SUM(C4:T4) -> 83.2 | Z4: =B4-W4 -> 334.6
A5: 45692 | B5: 90.4 | C5: 5 | F5: 13 | G5: 10.8 | K5: 26.7 | P5: 10 | W5: =SUM(C5:T5) -> 65.5 | Z5: =B5-W5 -> 24.9
A6: 45693 | B6: 124.6 | C6: 5 | D6: 60 | F6: 9 | I6: =3.2+4.51 -> 7.71 | K6: 1 | O6: 1 | W6: =SUM(C6:T6) -> 83.71 | Z6: =B6-W6 -> 40.89
A7: 45694 | B7: 180.4 | C7: 5 | D7: 68 | F7: 17 | G7: 22.35 | I7: 0.98 | K7: =1+1.5 -> 2.5 | W7: =SUM(C7:T7) -> 115.83 | Z7: =B7-W7 -> 64.57
A8: 45695 | F8: 33.9 | I8: 26.98 | W8: =SUM(C8:T8) -> 60.88 | Z8: =B8-W8 -> -60.88
A9: 45696 | B9: 12.8 | K9: =9.3+13.2 -> 22.5 | W9: =SUM(C9:T9) -> 22.5 | Z9: =B9-W9 -> -9.7
A10: 45697 | C10: 5 | D10: 50 | F10: 17 | G10: =6+6 -> 12 | I10: 24.6 | K10: =5+6.3 -> 11.3 | O10: 1 | Q10: 11 | W10: =SUM(C10:T10) -> 131.9 | X10: =sum(B4:B10) -> 826 | Y10: =sum(C4:T10) -> 563.52 | Z10: =B10-W10 -> -131.9 | AA10: =X10-Y10 -> 262.48
A11: 45698 | B11: 550.7 | C11: 7 | D11: 60 | F11: 13.7 | I11: 2 | K11: 5.5 | W11: =SUM(C11:T11) -> 88.2 | Z11: =B11-W11 -> 462.5
A12: 45699 | B12: 162.4 | C12: 7 | D12: 50 | F12: 13.5 | I12: 3.5 | W12: =SUM(C12:T12) -> 74 | Z12: =B12-W12 -> 88.4
A13: 45700 | B13: 292.4 | C13: 7 | D13: 60 | F13: 2 | G13: 9.5 | K13: 21.9 | W13: =SUM(C13:T13) -> 100.4 | Z13: =B13-W13 -> 192 | AB13: 540
A14: 45701 | B14: 392.1 | C14: 7 | D14: 65 | F14: 10 | I14: 3.12 | K14: =3.2+4.2 -> 7.4 | W14: =SUM(C14:T14) -> 92.52 | Z14: =B14-W14 -> 299.58
A15: 45702 | B15: 178.2 | C15: 7 | D15: 60 | F15: 11.5 | G15: 14 | I15: 4.51 | W15: =SUM(C15:T15) -> 97.01 | Z15: =B15-W15 -> 81.19
A16: 45703 | B16: 102.5 | C16: 7 | F16: 17 | G16: 17.5 | W16: =SUM(C16:T16) -> 41.5 | Z16: =B16-W16 -> 61
A17: 45704 | D17: 55 | N17: 49 | W17: =SUM(C17:T17) -> 104 | X17: =sum(B11:B17) -> 1678.3 | Y17: =sum(C11:T17) -> 597.63 | Z17: =B17-W17 -> -104 | AA17: =X17-Y17 -> 1080.67
A18: 45705 | B18: 423.1 | C18: 7 | D18: 60 | F18: 11.7 | W18: =SUM(C18:T18) -> 78.7 | Z18: =B18-W18 -> 344.4
A19: 45706 | B19: 371.2 | C19: 7 | D19: 60 | F19: 11.5 | I19: 4.43 | K19: 7.1 | W19: =SUM(C19:T19) -> 90.03 | Z19: =B19-W19 -> 281.17 | AB19: 600
A20: 45707 | B20: 309.6 | C20: 7 | D20: 60 | F20: 9 | K20: 10 | O20: 1 | W20: =SUM(C20:T20) -> 87 | Z20: =B20-W20 -> 222.6
A21: 45708 | B21: 110.4 | C21: 7 | D21: 60 | F21: 14.5 | G21: 13 | I21: =3.5+1.27 -> 4.77 | K21: 7.2 | W21: =SUM(C21:T21) -> 106.47 | Z21: =B21-W21 -> 3.93
A22: 45709 | B22: 270.4 | C22: 7 | D22: 60 | F22: 5.7 | G22: 12 | N22: 3.2 | O22: 5 | W22: =SUM(C22:T22) -> 92.9 | Z22: =B22-W22 -> 177.5
A23: 45710 | B23: 479.4 | C23: 7 | D23: 60 | F23: 8.3 | I23: 9 | W23: =SUM(C23:T23) -> 84.3 | Z23: =B23-W23 -> 395.1
A24: 45711 | B24: 105.9 | C24: 7 | D24: 60 | F24: 13 | G24: 10.3 | W24: =SUM(C24:T24) -> 90.3 | X24: =sum(B18:B24) -> 2070 | Y24: =sum(C18:T24) -> 629.7 | Z24: =B24-W24 -> 15.6 | AA24: =X24-Y24 -> 1440.3 | AB24: 1100
A25: 45712 | B25: 110.4 | C25: 7 | F25: 10.3 | G25: 4.5 | P25: 30 | W25: =SUM(C25:T25) -> 51.8 | Z25: =B25-W25 -> 58.6
A26: 45713 | D26: 60 | F26: 14 | H26: =220+220 -> 440 | I26: 5.5 | K26: 7.1 | U26: 15 | V26: Parking Expressionz | W26: =SUM(C26:U26) -> 541.6 | Z26: =B26-W26 -> -541.6
A27: 45714 | F27: =6.5+8 -> 14.5 | I27: 26.98 | L27: 70.19 | V27: 11 x 20W LED + 4 x LED Footer | W27: =SUM(C27:T27) -> 111.67 | Z27: =B27-W27 -> -111.67
A28: 45715 | D28: 60 | S28: 8.56 | W28: =SUM(C28:T28) -> 68.56 | Z28: =B28-W28 -> -68.56
A29: 45716 | T29: 200 | W29: =SUM(C29:T29) -> 200 | Z29: =B29-W29 -> -200
W30: =SUM(C30:T30) -> 0 | Z30: =B30-W30 -> 0
W31: =SUM(C31:T31) -> 0 | X31: =sum(B25:B31) -> 110.4 | Y31: =sum(C25:T31) -> 958.63 | Z31: =B31-W31 -> 0 | AA31: =X31-Y31 -> -848.23
W32: =X32-Y32 -> 0 | X32: =sum(B32) -> 0 | Y32: =sum(C32:T32) -> 0 | Z32: =B32-W32 -> 0
B33: =SUM(B2:B32) -> 5001.5 | C33: =SUM(C2:C32) -> 128 | D33: =SUM(D2:D32) -> 1188 | E33: =SUM(E2:E32) -> 0 | F33: =SUM(F2:F32) -> 312.1 | G33: =SUM(G2:G32) -> 125.95 | H33: =SUM(H2:H32) -> 440 | I33: =SUM(I2:I32) -> 124.08 | ... U33: =SUM(U2:U32) -> 15 | W33: =SUM(W2:W32) -> 3261.78
A34: Total : | B34: =B33-(C33+D33+E33+F33+G33+H33+I33+J33+K33+L33+M33+N33+O33+P33+Q33+R33+S33+T33+U33) -> 1739.72 | F34: =G33+F33 -> 438.05 | V34: Notes: | AA34: =B34/B33 -> 0.34783965

Sheet March
A1: Date | B1: Earning | C1: Insuran | D1: Minyak | F1: Makan | H1: Oil Filter | I1: TnG | J1: Maintenance | K1: Grocery | L1: Online Shop | M1: Hair Cut | N1: Subscription | O1: Charity | P1: Phone Bil | Q1: Laundry | R1: Rent | S1: Bil E&W | T1: Parent | U1: Other | V1: Remarks | W1: Total Spend | X1: Weekly Earning | Y1: Weekly Spend | Z1: Net Daily | AA1: Net Weekly
A2: 45717 | W2: =SUM(C2:V2) -> 0 | Z2: =B2-W2 -> 0
A3: 45718 | K3: 28.25 | W3: =SUM(C3:T3) -> 28.25 | X3: =B2+B3 -> 0 | Y3: =sum(C2:T3) -> 28.25 | Z3: =B3-W3 -> -28.25 | AA3: =X3-Y3 -> -28.25
A4: 45719 | W4: =SUM(C4:T4) -> 0 | Z4: =B4-W4 -> 0
A5: 45720 | R5: 350 | W5: =SUM(C5:T5) -> 350 | Z5: =B5-W5 -> -350
A6: 45721 | W6: =SUM(C6:T6) -> 0 | Z6: =B6-W6 -> 0
A7: 45722 | W7: =SUM(C7:T7) -> 0 | Z7: =B7-W7 -> 0
A8: 45723 | N8: 451.82 | V8: edraw software | W8: =SUM(C8:T8) -> 451.82 | Z8: =B8-W8 -> -451.82
A9: 45724 | W9: =SUM(C9:T9) -> 0 | Z9: =B9-W9 -> 0
A10: 45725 | L10: =34.82+30.83 -> 65.65 | V10: Net, Printer Lan Wire | W10: =SUM(C10:T10) -> 65.65 | X10: =sum(B4:B10) -> 0 | Y10: =sum(C4:T10) -> 867.47 | Z10: =B10-W10 -> -65.65 | AA10: =X10-Y10 -> -867.47
A11: 45726 | L11: 56.74 | V11: Hair Cliper | W11: =SUM(C11:T11) -> 56.74 | Z11: =B11-W11 -> -56.74
A12: 45727 | L12: 62.19 | W12: =SUM(C12:T12) -> 62.19 | Z12: =B12-W12 -> -62.19
A13: 45728 | W13: =SUM(C13:T13) -> 0 | Z13: =B13-W13 -> 0
A14: 45729 | W14: =SUM(C14:T14) -> 0 | Z14: =B14-W14 -> 0
A15: 45730 | L15: 32.7 | W15: =SUM(C15:T15) -> 32.7 | Z15: =B15-W15 -> -32.7
A16: 45731 | K16: 29.4 | W16: =SUM(C16:T16) -> 29.4 | Z16: =B16-W16 -> -29.4
A17: 45732 | L17: 60 | W17: =SUM(C17:T17) -> 60 | X17: =sum(B11:B17) -> 0 | Y17: =sum(C11:T17) -> 241.03 | Z17: =B17-W17 -> -60 | AA17: =X17-Y17 -> -241.03
A18: 45733 | W18: =SUM(C18:T18) -> 0 | Z18: =B18-W18 -> 0
A19: 45734 | W19: =SUM(C19:T19) -> 0 | Z19: =B19-W19 -> 0
A20: 45735 | K20: =23.2+31.4 -> 54.6 | W20: =SUM(C20:T20) -> 54.6 | Z20: =B20-W20 -> -54.6
A21: 45736 | N21: 299.8 | V21: movavi | W21: =SUM(C21:T21) -> 299.8 | Z21: =B21-W21 -> -299.8
A22: 45737 | W22: =SUM(C22:T22) -> 0 | Z22: =B22-W22 -> 0
A23: 45738 | W23: =SUM(C23:T23) -> 0 | Z23: =B23-W23 -> 0
A24: 45739 | O24: 10 | V24: zakat | W24: =SUM(C24:T24) -> 10 | X24: =sum(B18:B24) -> 0 | Y24: =sum(C18:T24) -> 364.4 | Z24: =B24-W24 -> -10 | AA24: =X24-Y24 -> -364.4
A25: 45740 | W25: =SUM(C25:T25) -> 0 | Z25: =B25-W25 -> 0
A26: 45741 | L26: 269.01 | V26: Microwave | W26: =SUM(C26:T26) -> 269.01 | Z26: =B26-W26 -> -269.01
A27: 45742 | D27: 60 | W27: =SUM(C27:T27) -> 60 | Z27: =B27-W27 -> -60
A28: 45743 | W28: =SUM(C28:T28) -> 0 | Z28: =B28-W28 -> 0
A29: 45744 | W29: =SUM(C29:T29) -> 0 | Z29: =B29-W29 -> 0
A30: 45745 | K30: 42.9 | W30: =SUM(C30:T30) -> 42.9 | Z30: =B30-W30 -> -42.9
A31: 45746
A32: 45747 | W32: =SUM(C32:T32) -> 0 | X32: =sum(B25:B32) -> 0 | Y32: =sum(C25:T32) -> 371.91 | Z32: =B32-W32 -> 0 | AA32: =X32-Y32 -> -371.91
W33: =X33-Y33 -> 0 | X33: =sum(B33) -> 0 | Y33: =sum(C33:T33) -> 0 | Z33: =B33-W33 -> 0
B34: =SUM(B2:B33) -> 0 | C34: =SUM(C2:C33) -> 0 | D34: =SUM(D2:D33) -> 60 | E34: =SUM(E2:E33) -> 0 | F34: =SUM(F2:F33) -> 0 | G34: =SUM(G2:G33) -> 0 | H34: =SUM(H2:H33) -> 0 | I34: =SUM(I2:I33) -> 0 | ... U34: =SUM(U2:U33) -> 0 | W34: =SUM(W2:W33) -> 1873.06
A35: Total : | B35: =B34-(C34+D34+E34+F34+G34+H34+I34+J34+K34+L34+M34+N34+O34+P34+Q34+R34+S34+T34+U34) -> -1873.06 | F35: =G34+F34 -> 0 | V35: Notes: | AA35: =B35/B34 -> #DIV/0!

Sheet April
A1: Date | B1: Earning | C1: Insuran | D1: Minyak | F1: Makan | H1: Oil Filter | I1: TnG | J1: Maintenance | K1: Grocery | L1: Online Shop | M1: Hair Cut | N1: Subscription | O1: Charity | P1: Phone Bil | Q1: Laundry | R1: Rent | S1: Bil E&W | T1: Parent | U1: Other | V1: Job | W1: 0+ | X1: 10+ | Y1: 20+ | Z1: 30+ | AA1: 40+ | AB1: 50+ | AC1: 60+ | AD1: 70 above | AE1: Total Job | AF1: Remarks | AG1: Total Spend | AH1: Weekly Earning | AI1: Weekly Spend | AJ1: Net Daily | AK1: Net Weekly | AL1: Cummulative | AM1: Deposit
A2: 45748 | D2: 65 | AG2: =Sum(C2:U2) -> 65 | AJ2: =B2-AG2 -> -65 | AL2: =AJ2 -> -65
A3: 45749 | C3: 7 | F3: 13 | AG3: =Sum(C3:U3) -> 20 | AJ3: =B3-AG3 -> -20 | AL3: =AL2+AJ3 -> -85
A4: 45750 | B4: 346 | C4: 7 | D4: 50 | E4: 50 | F4: 14 | I4: 0.85 | K4: 5.8 | O4: 2 | V4: 29 | W4: 19 | X4: 5 | Y4: 3 | AA4: 2 | AE4: =SUM(W4:AD4) -> 29 | AG4: =Sum(C4:U4) -> 129.65 | AJ4: =B4-AG4 -> 216.35 | AL4: =AL3+AJ4 -> 131.35
A5: 45751 | B5: 474.8 | C5: 7 | D5: 50 | E5: 50 | I5: 0.5 | K5: 5.8 | V5: 30 | W5: 18 | X5: 6 | Y5: 1 | Z5: 1 | AA5: 1 | AB5: 2 | AC5: 1 | AE5: =SUM(W5:AD5) -> 30 | AG5: =Sum(C5:U5) -> 113.3 | AJ5: =B5-AG5 -> 361.5 | AL5: =AL4+AJ5 -> 492.85
A6: 45752 | B6: 302.3 | C6: 7 | D6: 50 | F6: 11.3 | K6: 2.4 | L6: 5.7 | O6: 0.7 | V6: 26 | W6: 14 | X6: 10 | Y6: 1 | Z6: 1 | AE6: =SUM(W6:AD6) -> 26 | AG6: =Sum(C6:U6) -> 77.1 | AJ6: =B6-AG6 -> 225.2 | AL6: =AL5+AJ6 -> 718.05
A7: 45753 | B7: 362.1 | C7: 7 | D7: 60 | F7: 10.5 | K7: 2.4 | V7: 23 | W7: 11 | X7: 5 | Y7: 5 | Z7: 1 | AB7: 1 | AE7: =SUM(W7:AD7) -> 23 | AG7: =Sum(C7:U7) -> 79.9 | AH7: =sum(B2:B7) -> 1485.2 | AI7: =sum(AG2:AG7) -> 484.95 | AJ7: =B7-AG7 -> 282.2 | AK7: =sum(AJ2:AJ7) -> 1000.25 | AL7: =AL6+AJ7 -> 1000.25
A8: 45754 | B8: 404.52 | C8: 7 | D8: 55 | F8: 10 | K8: 8 | R8: 350 | V8: 35 | W8: 25 | X8: 7 | Y8: 2 | AA8: 1 | AE8: =SUM(W8:AD8) -> 35 | AG8: =Sum(C8:U8) -> 430 | AJ8: =B8-AG8 -> -25.48 | AL8: =AL7+AJ8 -> 974.77 | AM8: 650
A9: 45755 | B9: 302.4 | C9: 7 | D9: 60 | F9: 10.5 | G9: 20 | I9: 3.5 | S9: 13.17 | V9: 30 | W9: 20 | X9: 9 | AC9: 1 | AE9: =SUM(W9:AD9) -> 30 | AG9: =Sum(C9:U9) -> 114.17 | AJ9: =B9-AG9 -> 188.23 | AL9: =AL8+AJ9 -> 1163
A10: 45756 | B10: 304.9 | C10: 7 | D10: 60 | F10: 13.9 | K10: 9.7 | P10: 15 | V10: 25 | W10: 18 | X10: 4 | Y10: 1 | Z10: 1 | AC10: 1 | AE10: =SUM(W10:AD10) -> 25 | AG10: =Sum(C10:U10) -> 105.6 | AJ10: =B10-AG10 -> 199.3 | AL10: =AL9+AJ10 -> 1362.3
A11: 45757 | B11: 361.1 | C11: 7 | D11: 55 | E11: 60 | F11: 10 | I11: =3.2+0.66 -> 3.86 | V11: 30 | W11: 14 | X11: 10 | Y11: 6 | AE11: =SUM(W11:AD11) -> 30 | AG11: =Sum(C11:U11) -> 135.86 | AJ11: =B11-AG11 -> 225.24 | AL11: =AL10+AJ11 -> 1587.54
A12: 45758 | B12: 350.7 | C12: 7 | D12: 65 | F12: 15 | G12: 12 | V12: 22 | W12: 10 | X12: 7 | Y12: 2 | Z12: 1 | AA12: 1 | AB12: 1 | AE12: =SUM(W12:AD12) -> 22 | AG12: =Sum(C12:U12) -> 99 | AJ12: =B12-AG12 -> 251.7 | AL12: =AL11+AJ12 -> 1839.24
A13: 45759 | B13: 319.8 | C13: 7 | D13: 70 | F13: 12.5 | G13: 13 | I13: 9 | V13: 31 | W13: 20 | X13: 8 | Y13: 2 | AA13: 1 | AE13: =SUM(W13:AD13) -> 31 | AG13: =Sum(C13:U13) -> 111.5 | AJ13: =B13-AG13 -> 208.3 | AL13: =AL12+AJ13 -> 2047.54
A14: 45760 | B14: 516 | C14: 7 | D14: 65 | F14: 14.5 | I14: 8.53 | K14: =4.1+7.3 -> 11.4 | P14: 10 | V14: 37 | W14: 16 | X14: 16 | Y14: 1 | Z14: 4 | AE14: =SUM(W14:AD14) -> 37 | AG14: =Sum(C14:U14) -> 116.43 | AH14: =Sum(B8:B14) -> 2559.42 | AI14: =sum(AG8:AG14) -> 1112.56 | AJ14: =B14-AG14 -> 399.57 | AK14: =sum(AJ8:AJ14) -> 1446.86 | AL14: =AL13+AJ14 -> 2447.11
A15: 45761 | B15: 407.2 | C15: 7 | D15: 50 | F15: 15.5 | I15: 4.5 | V15: 25 | W15: 10 | X15: 9 | Y15: 5 | AD15: 1 | AE15: =SUM(W15:AD15) -> 25 | AG15: =Sum(C15:U15) -> 77 | AJ15: =B15-AG15 -> 330.2 | AL15: =AL14+AJ15 -> 2777.31 | AM15: 1470
A16: 45762 | B16: 308.1 | C16: 7 | D16: 60 | F16: 11 | G16: 17 | K16: 6.5 | V16: 19 | W16: 10 | X16: 3 | Y16: 4 | Z16: 1 | AD16: 1 | AE16: =SUM(W16:AD16) -> 19 | AG16: =Sum(C16:U16) -> 101.5 | AJ16: =B16-AG16 -> 206.6 | AL16: =AL15+AJ16 -> 2983.91
A17: 45763 | B17: 307.6 | C17: 7 | D17: 65 | F17: 21.5 | K17: 8.4 | V17: 19 | W17: 7 | X17: 7 | Y17: 3 | Z17: 1 | AC17: 1 | AE17: =SUM(W17:AD17) -> 19 | AG17: =Sum(C17:U17) -> 101.9 | AJ17: =B17-AG17 -> 205.7 | AL17: =AL16+AJ17 -> 3189.61 | AM17: 440
A18: 45764 | B18: 300.1 | C18: 7 | D18: 55 | F18: 8.5 | G18: 15 | I18: 3.5 | V18: 23 | W18: 13 | X18: 5 | Y18: 4 | AA18: 1 | AE18: =SUM(W18:AD18) -> 23 | AG18: =Sum(C18:U18) -> 89 | AJ18: =B18-AG18 -> 211.1 | AL18: =AL17+AJ18 -> 3400.71
A19: 45765 | B19: 315.6 | C19: 7 | D19: 65 | F19: 10 | V19: 19 | W19: 10 | X19: 4 | Y19: 4 | AB19: 1 | AE19: =SUM(W19:AD19) -> 19 | AG19: =Sum(C19:U19) -> 82 | AJ19: =B19-AG19 -> 233.6 | AL19: =AL18+AJ19 -> 3634.31
A20: 45766 | B20: 402.1 | C20: 7 | D20: 55 | E20: 60 | F20: 12 | Q20: 11 | V20: 19 | W20: 7 | X20: 5 | Y20: 2 | Z20: 3 | AA20: 1 | AD20: 1 | AE20: =SUM(W20:AD20) -> 19 | AG20: =Sum(C20:U20) -> 145 | AJ20: =B20-AG20 -> 257.1 | AL20: =AL19+AJ20 -> 3891.41
A21: 45767 | B21: 365.1 | C21: 7 | D21: 50 | F21: 8.8 | G21: 13 | I21: 3.2 | V21: 23 | W21: 10 | X21: 7 | Y21: 2 | Z21: 2 | AA21: 1 | AB21: 1 | AE21: =SUM(W21:AD21) -> 23 | AG21: =Sum(C21:U21) -> 82 | AH21: =Sum(B15:B21) -> 2405.8 | AI21: =sum(AG15:AG21) -> 678.4 | AJ21: =B21-AG21 -> 283.1 | AK21: =sum(AJ15:AJ21) -> 1727.4 | AL21: =AL20+AJ21 -> 4174.51
A22: 45768 | B22: 313.6 | C22: 7 | D22: 65 | F22: 5.6 | G22: 17.4 | K22: 9.4 | V22: 25 | AE22: =SUM(W22:AD22) -> 0 | AF22: Maggie | AG22: =Sum(C22:U22) -> 104.4 | AJ22: =B22-AG22 -> 209.2 | AL22: =AL21+AJ22 -> 4383.71
A23: 45769 | B23: 265.6 | C23: 7 | D23: 50 | F23: 6 | G23: 11.5 | I23: 4 | V23: 27 | AE23: =SUM(W23:AD23) -> 0 | AG23: =Sum(C23:U23) -> 78.5 | AJ23: =B23-AG23 -> 187.1 | AL23: =AL22+AJ23 -> 4570.81
A24: 45770 | B24: 203 | C24: 7 | D24: 60 | G24: 11.5 | I24: 6.4 | K24: 11.9 | V24: 19 | AE24: =SUM(W24:AD24) -> 0 | AG24: =Sum(C24:U24) -> 96.8 | AJ24: =B24-AG24 -> 106.2 | AL24: =AL23+AJ24 -> 4677.01 | AM24: 890
A25: 45771 | B25: 402.2 | C25: 7 | D25: 60 | F25: 8 | G25: 11 | I25: =2.5+4.2 -> 6.7 | V25: 27 | AE25: =SUM(W25:AD25) -> 0 | AG25: =Sum(C25:U25) -> 92.7 | AJ25: =B25-AG25 -> 309.5 | AL25: =AL24+AJ25 -> 4986.51
A26: 45772 | B26: 208.8 | C26: 7 | D26: 60 | F26: =2.9+11.3 -> 14.2 | I26: =1+6.04 -> 7.04 | V26: 15 | AE26: =SUM(W26:AD26) -> 0 | AG26: =Sum(C26:U26) -> 88.24 | AJ26: =B26-AG26 -> 120.56 | AL26: =AL25+AJ26 -> 5107.07
A27: 45773 | B27: 223.6 | D27: 60 | F27: 8 | G27: 12.5 | I27: 7 | N27: 10 | V27: 15 | AE27: =SUM(W27:AD27) -> 0 | AG27: =Sum(C27:U27) -> 97.5 | AJ27: =B27-AG27 -> 126.1 | AL27: =AL26+AJ27 -> 5233.17
A28: 45774 | B28: 258.6 | C28: 7 | D28: 68 | F28: 16.6 | I28: 9 | N28: 15.9 | V28: 20 | AE28: =SUM(W28:AD28) -> 0 | AG28: =Sum(C28:U28) -> 116.5 | AH28: =Sum(B22:B28) -> 1875.4 | AI28: =sum(AG22:AG28) -> 674.64 | AJ28: =B28-AG28 -> 142.1 | AK28: =sum(AJ22:AJ28) -> 1200.76 | AL28: =AL27+AJ28 -> 5375.27
A29: 45775 | B29: 404.4 | C29: 7 | D29: 55 | E29: 60 | F29: 18 | V29: 25 | AE29: =SUM(W29:AD29) -> 0 | AG29: =Sum(C29:U29) -> 140 | AJ29: =B29-AG29 -> 264.4 | AL29: =AL28+AJ29 -> 5639.67
A30: 45776 | B30: 207 | C30: 7 | D30: 70 | F30: 12 | I30: 3.5 | K30: 4.7 | V30: 22 | AE30: =SUM(W30:AD30) -> 0 | AG30: =Sum(C30:U30) -> 97.2 | AJ30: =B30-AG30 -> 109.8 | AL30: =AL29+AJ30 -> 5749.47
A31: 45777 | B31: 334.8 | C31: 7 | D31: 60 | F31: 15 | G31: 7.4 | I31: 3.5 | V31: 23 | AE31: =SUM(W31:AD31) -> 0 | AG31: =Sum(C31:U31) -> 92.9 | AH31: =sum(B29:B31) -> 946.2 | AI31: =sum(AG29:AG31) -> 330.1 | AJ31: =B31-AG31 -> 241.9 | AK31: =sum(AJ29:AJ31) -> 616.1 | AL31: =AL30+AJ31 -> 5991.37
A34: =count(B2:B31,"number")&" "&"/"&" "&countif(B2:B31,"") -> 28 / 2 | B34: =SUM(B2:B33) -> 9272.02 | C34: =SUM(C2:C33) -> 196 | D34: =SUM(D2:D33) -> 1713 | E34: =SUM(E2:E33) -> 280 | F34: =SUM(F2:F33) -> 325.9 | G34: =SUM(G2:G33) -> 161.3 | H34: =SUM(H2:H33) -> 0 | I34: =SUM(I2:I33) -> 84.58 | ... U34: =SUM(U2:U33) -> 0 | AG34: =SUM(AG2:AG33) -> 3280.65
A35: Total : | B35: =B34-(C34+D34+E34+F34+G34+H34+I34+J34+K34+L34+M34+N34+O34+P34+Q34+R34+S34+T34+U34) -> 5991.37 | D35: =D34+E34 -> 1993 | F35: =G34+F34 -> 487.2 | J35: >500 | K35: 400-499.99 | L35: 300-399.99 | M35: 200-299.99 | N35: 100-199.99 | O35: 0-99.99 | AF35: Notes: | AK35: =B35/B34 -> 0.64617742

Sheet May
A1: Date | B1: Earning | C1: Insuran | D1: Minyak | F1: Makan | H1: Oil Filter | I1: TnG | J1: Maintenance | K1: Grocery | L1: Online Shop | M1: Hair Cut | N1: Subscription | O1: Charity | P1: Phone Bil | Q1: Laundry | R1: Rent | S1: Bil E&W | T1: Parent | U1: Other | V1: Job | W1: Remarks | X1: Total Spend | Y1: Weekly Earning | Z1: Weekly Spend | AA1: Net Daily | AB1: Net Weekly | AC1: Cummulative | AD1: Deposit
A2: 45778 | B2: 307.2 | C2: 7 | D2: 65 | F2: 12 | G2: 17 | I2: =1.66+4.6 -> 6.26 | Q2: 11 | R2: 350 | V2: 23 | W2: nasi lemak burung hantu | X2: =sum(C2:U2) -> 468.26 | AA2: =B2-X2 -> -161.06 | AC2: =AA2 -> -161.06
A3: 45779 | B3: 304.4 | C3: 7 | D3: 65 | F3: 7.7 | G3: 10 | K3: =8.4+13.2 -> 21.6 | V3: 25 | X3: =sum(C3:U3) -> 111.3 | AA3: =B3-X3 -> 193.1 | AC3: =AC2+AA3 -> 32.04 | AD3: 1230
A4: 45780 | B4: 341.2 | C4: 7 | D4: 60 | F4: 11.5 | I4: 7.46 | V4: 25 | X4: =sum(C4:U4) -> 85.96 | AA4: =B4-X4 -> 255.24 | AC4: =AC3+AA4 -> 287.28
A5: 45781 | B5: 307.2 | C5: 7 | D5: 55 | F5: 8.5 | G5: 10 | I5: 6 | N5: 30 | V5: 22 | W5: maxis | X5: =sum(C5:U5) -> 116.5 | Y5: =sum(B2:B5)+April!AH31 -> 2206.2 | Z5: =sum(X2:X5)+April!AI31 -> 1112.12 | AA5: =B5-X5 -> 190.7 | AB5: =Y5-Z5+April!AK31 -> 1710.18 | AC5: =AC4+AA5 -> 477.98
A6: 45782 | B6: 300 | C6: 7 | D6: 60 | F6: 4 | G6: 14 | U6: =21+18 -> 39 | V6: 21 | W6: bloodbrother | X6: =sum(C6:U6) -> 124 | AA6: =B6-X6 -> 176 | AC6: =AC5+AA6 -> 653.98
A7: 45783 | B7: 305.2 | C7: 7 | D7: 50 | F7: 12 | G7: 9 | I7: 3.5 | V7: 26 | X7: =sum(C7:U7) -> 81.5 | AA7: =B7-X7 -> 223.7 | AC7: =AC6+AA7 -> 877.68
A8: 45784 | B8: 207.6 | C8: 7 | D8: 70 | F8: 11.6 | G8: 13.6 | V8: 20 | X8: =sum(C8:U8) -> 102.2 | AA8: =B8-X8 -> 105.4 | AC8: =AC7+AA8 -> 983.08
A9: 45785 | B9: 401.4 | C9: 7 | D9: 50 | E9: 66 | F9: 13.3 | I9: 7.46 | P9: 5 | V9: 29 | X9: =sum(C9:U9) -> 148.76 | AA9: =B9-X9 -> 252.64 | AC9: =AC8+AA9 -> 1235.72
A10: 45786 | B10: 274 | C10: 7 | D10: 55 | F10: 14 | G10: 11 | H10: 220 | I10: 3.43 | V10: 24 | W10: 15895.5 | X10: =sum(C10:U10) -> 310.43 | AA10: =B10-X10 -> -36.43 | AC10: =AC9+AA10 -> 1199.29
A11: 45787 | B11: 216.8 | C11: 7 | D11: 55 | F11: 10.5 | I11: 10 | V11: 15 | X11: =sum(C11:U11) -> 82.5 | AA11: =B11-X11 -> 134.3 | AC11: =AC10+AA11 -> 1333.59
A12: 45788 | B12: 512 | C12: 7 | D12: 60 | F12: 10 | G12: 12.5 | I12: 9 | K12: 8.5 | V12: 35 | X12: =sum(C12:U12) -> 107 | Y12: =sum(B6:B12) -> 2217 | Z12: =sum(X6:X12) -> 956.39 | AA12: =B12-X12 -> 405 | AB12: =Y12-Z12 -> 1260.61 | AC12: =AC11+AA12 -> 1738.59
A13: 45789 | B13: 205.6 | C13: 7 | D13: 50 | F13: 10.5 | G13: 13.9 | K13: 18.7 | V13: 20 | X13: =sum(C13:U13) -> 100.1 | AA13: =B13-X13 -> 105.5 | AC13: =AC12+AA13 -> 1844.09 | AD13: 1810
A14: 45790 | B14: 276.8 | C14: 7 | D14: 50 | E14: 50 | F14: 12.2 | I14: 12 | K14: 35.5 | V14: 22 | W14: Beras 10kg | X14: =sum(C14:U14) -> 166.7 | AA14: =B14-X14 -> 110.1 | AC14: =AC13+AA14 -> 1954.19
A15: 45791 | B15: 310 | C15: 7 | D15: 50 | E15: 60 | F15: 12.5 | G15: 11.5 | I15: 7 | V15: 26 | X15: =sum(C15:U15) -> 148 | AA15: =B15-X15 -> 162 | AC15: =AC14+AA15 -> 2116.19
A16: 45792 | B16: 201.6 | C16: 7 | D16: 60 | F16: =7+8 -> 15 | G16: 28 | I16: 4.43 | V16: 22 | X16: =sum(C16:U16) -> 114.43 | AA16: =B16-X16 -> 87.17 | AC16: =AC15+AA16 -> 2203.36
A17: 45793 | B17: 221.6 | C17: 7 | D17: 65 | F17: =12.5+10+5.2 -> 27.7 | G17: 14.75 | I17: 4.43 | K17: 11.2 | V17: 20 | X17: =sum(C17:U17) -> 130.08 | AA17: =B17-X17 -> 91.52 | AC17: =AC16+AA17 -> 2294.88
A18: 45794 | B18: 379.44 | C18: 7 | D18: 50 | F18: 17.5 | G18: 10 | I18: 3.5 | K18: 9.3 | T18: 200 | V18: 28 | W18: duit ayah | X18: =sum(C18:U18) -> 297.3 | AA18: =B18-X18 -> 82.14 | AC18: =AC17+AA18 -> 2377.02
A19: 45795 | B19: 244 | C19: 7 | D19: 55 | F19: 12.5 | G19: =7.1+6.5 -> 13.6 | I19: =3.5+2+3.5 -> 9 | V19: 29 | X19: =sum(C19:U19) -> 97.1 | Y19: =sum(B13:B19) -> 1839.04 | Z19: =sum(X13:X19) -> 1053.71 | AA19: =B19-X19 -> 146.9 | AB19: =Y19-Z19 -> 785.33 | AC19: =AC18+AA19 -> 2523.92
A20: 45796 | B20: =348.8+89.01 -> 437.81 | C20: 7 | D20: 55 | E20: 68 | F20: 12.5 | G20: =5+11.2 -> 16.2 | V20: 31 | X20: =sum(C20:U20) -> 158.7 | AA20: =B20-X20 -> 279.11 | AC20: =AC19+AA20 -> 2803.03 | AD20: 1000
A21: 45797 | B21: 239.2 | C21: 7 | D21: 69 | F21: =6+5 -> 11 | G21: 12.2 | V21: 23 | X21: =sum(C21:U21) -> 99.2 | AA21: =B21-X21 -> 140 | AC21: =AC20+AA21 -> 2943.03
A22: 45798 | B22: 375 | C22: 7 | D22: 66 | F22: 15.5 | G22: 7 | I22: =3.5+7.46 -> 10.96 | V22: 30 | X22: =sum(C22:U22) -> 106.46 | AA22: =B22-X22 -> 268.54 | AC22: =AC21+AA22 -> 3211.57
A23: 45799 | B23: 276.6 | C23: 7 | D23: 70 | F23: 14.5 | G23: 10 | V23: 21 | X23: =sum(C23:U23) -> 101.5 | AA23: =B23-X23 -> 175.1 | AC23: =AC22+AA23 -> 3386.67
A24: 45800 | B24: 295.2 | C24: 7 | D24: 70 | F24: 8 | G24: 11.15 | I24: 3.6 | V24: 25 | X24: =sum(C24:U24) -> 99.75 | AA24: =B24-X24 -> 195.45 | AC24: =AC23+AA24 -> 3582.12
A25: 45801 | B25: 375 | C25: 7 | D25: 60 | F25: 16.5 | G25: =15+10+5.4 -> 30.4 | I25: 4.26 | O25: 3 | V25: 38 | X25: =sum(C25:U25) -> 121.16 | AA25: =B25-X25 -> 253.84 | AC25: =AC24+AA25 -> 3835.96
A26: 45802 | B26: 313.6 | C26: 7 | D26: 60 | F26: =10+20 -> 30 | G26: 6 | I26: 4.26 | V26: 33 | W26: cempedak | X26: =sum(C26:U26) -> 107.26 | Y26: =sum(B20:B26) -> 2312.41 | Z26: =sum(X20:X26) -> 794.03 | AA26: =B26-X26 -> 206.34 | AB26: =Y26-Z26 -> 1518.38 | AC26: =AC25+AA26 -> 4042.3
A27: 45803 | B27: 317.2 | C27: 7 | D27: 66 | F27: 12.2 | I27: 7.4 | K27: =7.4+14.35 -> 21.75 | V27: 12 | X27: =sum(C27:U27) -> 114.35 | AA27: =B27-X27 -> 202.85 | AC27: =AC26+AA27 -> 4245.15
A28: 45804 | B28: 507.18 | C28: 7 | D28: 65 | F28: 12 | I28: 3.85 | V28: 26 | X28: =sum(C28:U28) -> 87.85 | AA28: =B28-X28 -> 419.33 | AC28: =AC27+AA28 -> 4664.48
A29: 45805 | B29: 222.6 | C29: 7 | D29: 65 | F29: 11.5 | G29: 10 | I29: 3.5 | V29: 22 | X29: =sum(C29:U29) -> 97 | AA29: =B29-X29 -> 125.6 | AC29: =AC28+AA29 -> 4790.08 | AD29: 1330
A30: 45806 | B30: 308.6 | C30: 7 | D30: 65 | F30: 15.9 | I30: 3.5 | V30: 26 | X30: =sum(C30:U30) -> 91.4 | AA30: =B30-X30 -> 217.2 | AC30: =AC29+AA30 -> 5007.28
A31: 45807 | B31: 201.6 | C31: 7 | D31: 65 | F31: 15.5 | G31: 11.5 | I31: =3.12+6 -> 9.12 | K31: 11.5 | Q31: 16 | S31: 12.57 | V31: 20 | X31: =sum(C31:U31) -> 148.19 | AA31: =B31-X31 -> 53.41 | AC31: =AC30+AA31 -> 5060.69
A32: 45808 | B32: 328.84 | C32: 7 | D32: 50 | E32: 65 | F32: 14.5 | G32: 13 | I32: 3.5 | O32: 15.9 | V32: 25 | X32: =sum(C32:U32) -> 168.9 | Y32: =sum(B27:B32) -> 1886.02 | Z32: =sum(X27:X32) -> 707.69 | AA32: =B32-X32 -> 159.94 | AB32: =Y32-Z32 -> 1178.33 | AC32: =AC31+AA32 -> 5220.63
A34: =count(B2:B32,"number")&" "&"/"&" "&countif(B2:B32,"") -> 31 / 0 | B34: =SUM(B2:B33) -> 9514.47 | C34: =SUM(C2:C33) -> 217 | D34: =SUM(D2:D33) -> 1851 | E34: =SUM(E2:E33) -> 309 | F34: =SUM(F2:F33) -> 412.6 | G34: =SUM(G2:G33) -> 316.3 | H34: =SUM(H2:H33) -> 220 | I34: =SUM(I2:I33) -> 147.42 | ... U34: =SUM(U2:U33) -> 39 | X34: =SUM(X2:X33) -> 4293.84
A35: Total : | B35: =B34-(C34+D34+E34+F34+G34+H34+I34+J34+K34+L34+M34+N34+O34+P34+Q34+R34+S34+T34+U34) -> 5220.63 | D35: =D34+E34 -> 2160 | F35: =G34+F34 -> 728.9 | J35: >500 | K35: 400-499.99 | L35: 300-399.99 | M35: 200-299.99 | N35: 100-199.99 | O35: 0-99.99 | W35: Notes: | AB35: =B35/B34 -> 0.54870424

Sheet June
A1: Date | B1: Earning | C1: Insuran | D1: Minyak | F1: Makan | H1: Oil Filter | I1: TnG | J1: Maintenance | K1: Grocery | L1: Online Shop | M1: Hair Cut | N1: Subscription | O1: Charity | P1: Phone Bil | Q1: Laundry | R1: Rent | S1: Bil E&W | T1: Parent | U1: Other | V1: Job | W1: Remarks | X1: Total Spend | Y1: Weekly Earning | Z1: Weekly Spend | AA1: Net Daily | AB1: Net Weekly | AC1: Cummulative | AD1: Deposit
A2: 45809 | B2: 252.8 | C2: 7 | D2: 60 | F2: 12 | G2: =10+7.5 -> 17.5 | I2: =3.12+2.3 -> 5.42 | V2: 22 | X2: =sum(C2:U2) -> 101.92 | Y2: =sum(B2) -> 252.8 | Z2: =sum(X2) -> 101.92 | AA2: =B2-X2 -> 150.88 | AB2: =AA2+May!AB32 -> 1329.21 | AC2: =AA2 -> 150.88
A3: 45810 | B3: 286 | C3: 7 | D3: 70 | F3: 14.5 | G3: 14 | I3: =2.4+5.66 -> 8.06 | K3: 4.6 | L3: =10.08+11.45 -> 21.53 | U3: 20 | V3: 25 | W3: cuci kereta | X3: =sum(C3:W3) -> 184.69 | AA3: =B3-X3 -> 101.31 | AC3: =AC2+AA3 -> 252.19
A4: 45811 | B4: 447.01 | C4: 7 | D4: 70 | F4: 8 | G4: 13.9 | H4: 220 | I4: 6 | T4: 200 | V4: 25 | X4: =sum(C4:U4) -> 524.9 | AA4: =B4-X4 -> -77.89 | AC4: =AC3+AA4 -> 174.3
A5: 45812 | B5: 403.8 | C5: 7 | D5: 68 | F5: 13 | G5: =6+8.2 -> 14.2 | I5: =3.12+2.7 -> 5.82 | V5: 23 | X5: =sum(C5:U5) -> 108.02 | AA5: =B5-X5 -> 295.78 | AC5: =AC4+AA5 -> 470.08 | AD5: 830
A6: 45813 | B6: 503.8 | C6: 7 | D6: 70 | F6: 20.3 | G6: 10.2 | I6: 3.2 | V6: 30 | X6: =sum(C6:U6) -> 110.7 | AA6: =B6-X6 -> 393.1 | AC6: =AC5+AA6 -> 863.18
A7: 45814 | B7: 451.2 | C7: 7 | D7: 60 | E7: 50 | F7: 6.2 | G7: 15.9 | V7: 29 | X7: =sum(C7:U7) -> 139.1 | AA7: =B7-X7 -> 312.1 | AC7: =AC6+AA7 -> 1175.28
A8: 45815 | B8: 517.4 | C8: 7 | D8: 70 | F8: 10.8 | R8: 350 | V8: 24 | X8: =sum(C8:U8) -> 437.8 | AA8: =B8-X8 -> 79.6 | AC8: =AC7+AA8 -> 1254.88
A9: 45816 | B9: 572 | C9: 7 | D9: 65 | V9: 30 | X9: =sum(C9:U9) -> 72 | Y9: =sum(B3:B9) -> 3181.21 | Z9: =sum(X3:X9) -> 1577.21 | AA9: =B9-X9 -> 500 | AB9: =sum(AA3:AA9) -> 1604 | AC9: =AC8+AA9 -> 1754.88
A10: 45817 | B10: =440.6+286.56 -> 727.16 | C10: 7 | D10: 60 | F10: 14 | K10: 8.4 | V10: 43 | W10: petron | X10: =sum(C10:U10) -> 89.4 | AA10: =B10-X10 -> 637.76 | AC10: =AC9+AA10 -> 2392.64
A11: 45818 | B11: 402.4 | C11: 7 | D11: 68 | E11: 65 | F11: 11.9 | G11: 6 | I11: =3+2.4+3.5 -> 8.9 | U11: 32.8 | V11: 18 | W11: earphone | X11: =sum(C11:U11) -> 199.6 | AA11: =B11-X11 -> 202.8 | AC11: =AC10+AA11 -> 2595.44
A12: 45819 | B12: 216 | C12: 7 | D12: 65 | F12: 13.5 | G12: 10 | I12: 3.5 | K12: 12.45 | U12: 10 | V12: 21 | W12: Saman parking KW | X12: =sum(C12:U12) -> 121.45 | AA12: =B12-X12 -> 94.55 | AC12: =AC11+AA12 -> 2689.99
A13: 45820 | B13: 231 | C13: 7 | D13: 65 | F13: 11 | G13: 11.15 | I13: 3.2 | J13: =220+180 -> 400 | K13: =13+4.9 -> 17.9 | V13: 16 | W13: Service(298211,13990) , brakepad(depan) | X13: =sum(C13:U13) -> 515.25 | AA13: =B13-X13 -> -284.25 | AC13: =AC12+AA13 -> 2405.74 | AD13: 2330
A14: 45821 | B14: 204.88 | C14: 7 | D14: 60 | F14: 12 | G14: 15.6 | I14: 3.2 | K14: 5.8 | Q14: 12 | V14: 15 | X14: =sum(C14:U14) -> 115.6 | AA14: =B14-X14 -> 89.28 | AC14: =AC13+AA14 -> 2495.02
A15: 45822 | B15: 202 | C15: 7 | D15: 60 | F15: 5.6 | G15: =10.9+2.4 -> 13.3 | I15: 2 | K15: 83 | V15: 13 | W15: watson | X15: =sum(C15:U15) -> 170.9 | AA15: =B15-X15 -> 31.1 | AC15: =AC14+AA15 -> 2526.12
A16: 45823 | B16: 202.4 | C16: 7 | D16: 60 | F16: =29 -> 29 | G16: =9.8+5 -> 14.8 | I16: 4.51 | V16: 15 | W16: aircond rosak | X16: =sum(C16:U16) -> 115.31 | Y16: =sum(B10:B16) -> 2185.84 | Z16: =sum(X10:X16) -> 1327.51 | AA16: =B16-X16 -> 87.09 | AB16: =sum(AA10:AA16) -> 858.33 | AC16: =AC15+AA16 -> 2613.21
A17: 45824 | B17: 276.17 | C17: 7 | D17: 55 | F17: 12 | G17: 11.5 | I17: 6 | J17: =320+40 -> 360 | N17: 35 | V17: 13 | W17: repair aircond (tukar motor denso) + aircond filter | X17: =sum(C17:U17) -> 486.5 | AA17: =B17-X17 -> -210.33 | AC17: =AC16+AA17 -> 2402.88
A18: 45825 | B18: 205.6 | C18: 7 | D18: 55 | F18: 15 | G18: 19 | K18: 7.6 | V18: 20 | X18: =sum(C18:U18) -> 103.6 | AA18: =B18-X18 -> 102 | AC18: =AC17+AA18 -> 2504.88
A19: 45826 | B19: 256.24 | C19: 7 | D19: 60 | F19: 5 | G19: 13.5 | I19: 6 | V19: 20 | X19: =sum(C19:U19) -> 91.5 | AA19: =B19-X19 -> 164.74 | AC19: =AC18+AA19 -> 2669.62
A20: 45827 | B20: 244 | C20: 7 | D20: 55 | F20: 10 | G20: 11.9 | I20: 6 | V20: 19 | X20: =sum(C20:U20) -> 89.9 | AA20: =B20-X20 -> 154.1 | AC20: =AC19+AA20 -> 2823.72
A21: 45828 | B21: 279.2 | C21: 7 | D21: 55 | F21: 12 | G21: 15.5 | I21: 3.5 | K21: 5.9 | V21: 20 | X21: =sum(C21:U21) -> 98.9 | AA21: =B21-X21 -> 180.3 | AC21: =AC20+AA21 -> 3004.02
A22: 45829 | B22: 206.68 | C22: 7 | D22: 60 | F22: 11.5 | I22: 3.5 | V22: 16 | X22: =sum(C22:U22) -> 82 | AA22: =B22-X22 -> 124.68 | AC22: =AC21+AA22 -> 3128.7
A23: 45830 | B23: 313.6 | C23: 7 | D23: 65 | F23: 5 | G23: 18 | I23: 7.46 | K23: 7.5 | V23: 25 | X23: =sum(C23:U23) -> 109.96 | Y23: =sum(B17:B23) -> 1781.49 | Z23: =sum(X17:X23) -> 1062.36 | AA23: =B23-X23 -> 203.64 | AB23: =sum(AA17:AA23) -> 719.13 | AC23: =AC22+AA23 -> 3332.34
A24: 45831 | B24: 293.2 | C24: 7 | D24: 68 | F24: 6 | G24: 12 | I24: =3.5+3.2 -> 6.7 | K24: 10.1 | V24: 22 | X24: =sum(C24:U24) -> 109.8 | AA24: =B24-X24 -> 183.4 | AC24: =AC23+AA24 -> 3515.74
A25: 45832 | B25: 337.6 | C25: 7 | D25: 60 | F25: 10 | G25: =12.5+9 -> 21.5 | V25: 25 | X25: =sum(C25:U25) -> 98.5 | AA25: =B25-X25 -> 239.1 | AC25: =AC24+AA25 -> 3754.84 | AD25: 1500
A26: 45833 | B26: 320 | C26: 7 | D26: 60 | F26: 13.5 | G26: 14.8 | V26: 26 | X26: =sum(C26:U26) -> 95.3 | AA26: =B26-X26 -> 224.7 | AC26: =AC25+AA26 -> 3979.54
A27: 45834 | B27: 450.4 | C27: 7 | D27: 65 | F27: 11 | G27: 8 | K27: 9.7 | V27: 28 | X27: =sum(C27:U27) -> 100.7 | AA27: =B27-X27 -> 349.7 | AC27: =AC26+AA27 -> 4329.24
A28: 45835 | B28: 211.8 | C28: 7 | D28: 55 | F28: 11.5 | G28: 11.5 | I28: =3.2+2.1+2.1+3.2 -> 10.6 | V28: 17 | X28: =sum(C28:U28) -> 95.6 | AA28: =B28-X28 -> 116.2 | AC28: =AC27+AA28 -> 4445.44
A29: 45836 | B29: 359.6 | C29: 7 | D29: 65 | F29: 10.5 | G29: 15 | I29: 3.2 | K29: =6.2+18.9+15+4.1 -> 44.2 | V29: 26 | W29: rotiboy,sabun,satay,n.dagang | X29: =sum(C29:U29) -> 144.9 | AA29: =B29-X29 -> 214.7 | AC29: =AC28+AA29 -> 4660.14 | AD29: 1150
A30: 45837 | B30: 311.6 | C30: 7 | D30: 55 | F30: 10 | G30: 11.4 | K30: 16.05 | O30: 11.2 | V30: 27 | X30: =sum(C30:U30) -> 110.65 | Y30: =sum(B24:B30) -> 2284.2 | Z30: =sum(X24:X30) -> 755.45 | AA30: =B30-X30 -> 200.95 | AB30: =sum(AA24:AA30) -> 1528.75 | AC30: =AC29+AA30 -> 4861.09
A31: 45838 | B31: 480.96 | C31: 7 | D31: 55 | F31: 14.1 | G31: 12 | I31: 3.2 | V31: 27 | X31: =sum(C31:U31) -> 91.3 | Y31: =sum(B31) -> 480.96 | Z31: =sum(X31) -> 91.3 | AA31: =B31-X31 -> 389.66 | AB31: =AA31 -> 389.66 | AC31: =AC30+AA31 -> 5250.75
A34: =count(B2:B31,"number")&" "&"/"&" "&countif(B2:B31,"") -> 30 / 0 | B34: =SUM(B2:B33) -> 10166.5 | C34: =SUM(C2:C33) -> 210 | D34: =SUM(D2:D33) -> 1859 | E34: =SUM(E2:E33) -> 115 | F34: =SUM(F2:F33) -> 338.9 | G34: =SUM(G2:G33) -> 352.15 | H34: =SUM(H2:H33) -> 220 | I34: =SUM(I2:I33) -> 109.97 | ... U34: =SUM(U2:U33) -> 62.8 | X34: =SUM(X2:X33) -> 4915.75
A35: Total : | B35: =B34-(C34+D34+E34+F34+G34+H34+I34+J34+K34+L34+M34+N34+O34+P34+Q34+R34+S34+T34+U34) -> 5275.75 | D35: =D34+E34 -> 1974 | F35: =G34+F34 -> 691.05 | J35: >500 | K35: 400-499.99 | L35: 300-399.99 | M35: 200-299.99 | N35: 100-199.99 | O35: 0-99.99 | W35: Notes: | AB35: =B35/B34 -> 0.51893474

Sheet July
A1: Date | B1: Earning | C1: Insuran | D1: Minyak | F1: Makan | H1: Oil Filter | I1: TnG | J1: Maintenance | K1: Grocery | L1: Online Shop | M1: Hair Cut | N1: Subscription | O1: Charity | P1: Phone Bil | Q1: Laundry | R1: Rent | S1: Bil E&W | T1: Parent | U1: Other | V1: Job | W1: Remarks | X1: Total Spend | Y1: Weekly Earning | Z1: Weekly Spend | AA1: Net Daily | AB1: Net Weekly | AC1: Cummulative
A2: 45839 | B2: 238.64 | C2: 7 | D2: 50 | F2: 22 | G2: 22 | I2: =3.2+4.51 -> 7.71 | K2: =11.4+10.3 -> 21.7 | N2: 15.9 | O2: 200 | Q2: 11 | R2: 350 | T2: 200 | V2: 14 | W2: spotify | X2: =sum(C2:U2) -> 907.31 | AA2: =B2-X2 -> -668.67 | AC2: =AA2 -> -668.67
A3: 45840 | B3: 217.6 | C3: 7 | D3: 55 | E3: 65 | F3: 13.8 | I3: =4.76+2.3+6.07 -> 13.13 | K3: =29.5+5.7 -> 35.2 | V3: 13 | X3: =sum(C3:U3) -> 189.13 | AA3: =B3-X3 -> 28.47 | AC3: =AC2+AA3 -> -640.2
A4: 45841 | B4: 213.84 | C4: 7 | D4: 50 | F4: 20 | G4: 11.5 | I4: 8.5 | V4: 18 | X4: =sum(C4:U4) -> 97 | AA4: =B4-X4 -> 116.84 | AC4: =AC3+AA4 -> -523.36
A5: 45842 | B5: 262.4 | C5: 7 | F5: 11.5 | G5: 9.8 | I5: 4.51 | K5: 4.3 | V5: 25 | X5: =sum(C5:U5) -> 37.11 | AA5: =B5-X5 -> 225.29 | AC5: =AC4+AA5 -> -298.07
A6: 45843 | B6: 206.4 | D6: 68 | F6: 11 | K6: 6.2 | V6: 17 | X6: =sum(C6:U6) -> 85.2 | AA6: =B6-X6 -> 121.2 | AC6: =AC5+AA6 -> -176.87 | AD6: 1050
A7: 45844 | B7: 208.8 | C7: 7 | D7: 50 | F7: 19 | I7: 3.2 | K7: 10.9 | V7: 19 | W7: kebab b.bintang | X7: =sum(C7:U7) -> 90.1 | Y7: =sum(B2:B7) -> 1347.68 | Z7: =sum(X2:X7) -> 1405.85 | AA7: =B7-X7 -> 118.7 | AB7: =Y7-Z7 -> -58.17 | AC7: =AC6+AA7 -> -58.17
A8: 45845 | B8: 330.78 | C8: 7 | D8: 60 | F8: =9+11.5 -> 20.5 | G8: 16 | I8: 1 | K8: 6.1 | S8: 13 | V8: 21 | X8: =sum(C8:U8) -> 123.6 | AA8: =B8-X8 -> 207.18 | AC8: =AC7+AA8 -> 149.01
A9: 45846 | B9: 206.4 | C9: 7 | D9: 55 | F9: 5.9 | G9: =14+8.5 -> 22.5 | I9: 6.6 | V9: 19 | X9: =sum(C9:U9) -> 97 | AA9: =B9-X9 -> 109.4 | AC9: =AC8+AA9 -> 258.41
A10: 45847 | B10: 416.64 | C10: 7 | D10: 50 | F10: 20 | I10: 3.53 | J10: 175 | V10: 28 | W10: bateriku | X10: =sum(C10:U10) -> 255.53 | AA10: =B10-X10 -> 161.11 | AC10: =AC9+AA10 -> 419.52
A11: 45848 | B11: 314.4 | C11: 7 | D11: 60 | E11: 60 | F11: 12.5 | I11: =3.5+3.2 -> 6.7 | V11: 24 | X11: =sum(C11:U11) -> 146.2 | AA11: =B11-X11 -> 168.2 | AC11: =AC10+AA11 -> 587.72
A12: 45849 | B12: 401.64 | C12: 7 | D12: 65 | F12: 8.5 | I12: =1.66+2.46 -> 4.12 | V12: 28 | X12: =sum(C12:U12) -> 84.62 | AA12: =B12-X12 -> 317.02 | AC12: =AC11+AA12 -> 904.74
A13: 45850 | B13: 265.04 | C13: 7 | D13: 65 | F13: 13 | G13: 10 | I13: =2.1+2.1 -> 4.2 | P13: 36 | V13: 21 | X13: =sum(C13:U13) -> 135.2 | AA13: =B13-X13 -> 129.84 | AC13: =AC12+AA13 -> 1034.58
A14: 45851 | B14: 250.4 | C14: 7 | D14: 65 | F14: 14.5 | I14: =2.5+7.46 -> 9.96 | V14: 22 | X14: =sum(C14:U14) -> 96.46 | Y14: =sum(B8:B14) -> 2185.3 | Z14: =sum(X8:X14) -> 938.61 | AA14: =B14-X14 -> 153.94 | AB14: =Y14-Z14 -> 1246.69 | AC14: =AC13+AA14 -> 1188.52
A15: 45852 | B15: 439.45 | C15: 7 | D15: 50 | F15: 5.2 | G15: 15.72 | I15: =3.2+1.66+3.1 -> 7.96 | O15: 2 | V15: 15 | X15: =sum(C15:U15) -> 87.88 | AA15: =B15-X15 -> 351.57 | AC15: =AC14+AA15 -> 1540.09
A16: 45853 | B16: 276.6 | C16: 7 | D16: 70 | F16: 9 | G16: 10.5 | I16: 3.2 | V16: 22 | X16: =sum(C16:U16) -> 99.7 | AA16: =B16-X16 -> 176.9 | AC16: =AC15+AA16 -> 1716.99
A17: 45854 | B17: 266.4 | C17: 7 | F17: 17.5 | G17: 16.4 | I17: 2.5 | V17: 13 | X17: =sum(C17:U17) -> 43.4 | AA17: =B17-X17 -> 223 | AC17: =AC16+AA17 -> 1939.99
A18: 45855 | B18: 248.8 | C18: 7 | D18: 55 | E18: 60 | F18: 9 | G18: 11.5 | I18: 3.2 | K18: 1.5 | V18: 23 | X18: =sum(C18:U18) -> 147.2 | AA18: =B18-X18 -> 101.6 | AC18: =AC17+AA18 -> 2041.59 | AD18: 1700
A19: 45856 | B19: 244.8 | C19: 7 | F19: 9 | G19: 12 | K19: 8.8 | V19: 20 | X19: =sum(C19:U19) -> 36.8 | AA19: =B19-X19 -> 208 | AC19: =AC18+AA19 -> 2249.59
A20: 45857 | B20: 324.8 | C20: 7 | D20: 65 | E20: 65 | F20: 13 | G20: 17 | I20: 3.2 | V20: 26 | X20: =sum(C20:U20) -> 170.2 | AA20: =B20-X20 -> 154.6 | AC20: =AC19+AA20 -> 2404.19
A21: 45858 | B21: 411.2 | C21: 7 | D21: 60 | F21: 11.8 | I21: 6.8 | V21: 31 | X21: =sum(C21:U21) -> 85.6 | Y21: =sum(B15:B21) -> 2212.05 | Z21: =sum(X15:X21) -> 670.78 | AA21: =B21-X21 -> 325.6 | AB21: =Y21-Z21 -> 1541.27 | AC21: =AC20+AA21 -> 2729.79
A22: 45859 | B22: 407.2 | C22: 7 | D22: 65 | F22: 11 | G22: 20 | I22: =3.5+2.1+3.2 -> 8.8 | K22: 7.9 | V22: 31 | X22: =sum(C22:U22) -> 119.7 | AA22: =B22-X22 -> 287.5 | AC22: =AC21+AA22 -> 3017.29
A23: 45860 | B23: 439.77 | C23: 7 | D23: 60 | F23: 13 | I23: =3.2+3.2 -> 6.4 | V23: 28 | X23: =sum(C23:U23) -> 86.4 | AA23: =B23-X23 -> 353.37 | AC23: =AC22+AA23 -> 3370.66
A24: 45861 | B24: 324 | C24: 7 | D24: 60 | F24: 19 | I24: =2.54+4.6+3.5 -> 10.64 | V24: 31 | X24: =sum(C24:U24) -> 96.64 | AA24: =B24-X24 -> 227.36 | AC24: =AC23+AA24 -> 3598.02
A25: 45862 | B25: 310.4 | C25: 7 | D25: 60 | E25: 65 | G25: =12.8+15.4 -> 28.2 | V25: 27 | X25: =sum(C25:U25) -> 160.2 | AA25: =B25-X25 -> 150.2 | AC25: =AC24+AA25 -> 3748.22
A26: 45863 | B26: 401.6 | C26: 7 | D26: 50 | F26: 11.3 | I26: 3.53 | K26: 17.1 | V26: 33 | W26: grab system updated | X26: =sum(C26:U26) -> 88.93 | AA26: =B26-X26 -> 312.67 | AC26: =AC25+AA26 -> 4060.89
A27: 45864 | B27: 408.8 | C27: 7 | D27: 60 | F27: 7.7 | I27: =3+3.2 -> 6.2 | O27: 1 | V27: 24 | X27: =sum(C27:U27) -> 81.9 | AA27: =B27-X27 -> 326.9 | AC27: =AC26+AA27 -> 4387.79
A28: 45865 | B28: 405.6 | C28: 7 | D28: 70 | E28: 65 | F28: 20.8 | G28: 12 | I28: =3.54+6 -> 9.54 | V28: 23 | X28: =sum(C28:U28) -> 184.34 | Y28: =sum(B22:B28) -> 2697.37 | Z28: =sum(X22:X28) -> 818.11 | AA28: =B28-X28 -> 221.26 | AB28: =Y28-Z28 -> 1879.26 | AC28: =AC27+AA28 -> 4609.05
A29: 45866 | B29: 611.88 | C29: 7 | D29: 65 | E29: 55 | F29: 11.5 | G29: 7.5 | I29: =7+1+3.5 -> 11.5 | U29: 5 | V29: 28 | X29: =sum(C29:U29) -> 162.5 | AA29: =B29-X29 -> 449.38 | AC29: =AC28+AA29 -> 5058.43
A30: 45867 | B30: 303.3 | C30: 7 | D30: 70 | F30: 9 | G30: 11.5 | V30: 30 | X30: =sum(C30:U30) -> 97.5 | AA30: =B30-X30 -> 205.8 | AC30: =AC29+AA30 -> 5264.23
A31: 45868 | B31: 240.9 | C31: 7 | D31: 70 | F31: 6.5 | G31: 13.9 | V31: 25 | X31: =sum(C31:U31) -> 97.4 | AA31: =B31-X31 -> 143.5 | AC31: =AC30+AA31 -> 5407.73 | AD31: 1950
A32: 45869 | B32: 256.8 | C32: 7 | D32: 60 | F32: 21.4 | V32: 18 | X32: =sum(C32:U32) -> 88.4 | Y32: =sum(B29:B32) -> 1412.88 | Z32: =sum(X29:X32) -> 445.8 | AA32: =B32-X32 -> 168.4 | AB32: =Y32-Z32 -> 967.08 | AC32: =AC31+AA32 -> 5576.13
A34: =count(B2:B32,"number")&" "&"/"&" "&countif(B2:B32,"") -> 31 / 0 | B34: =SUM(B2:B33) -> 9855.28 | C34: =SUM(C2:C33) -> 210 | D34: =SUM(D2:D33) -> 1683 | E34: =SUM(E2:E33) -> 435 | F34: =SUM(F2:F33) -> 397.9 | G34: =SUM(G2:G33) -> 268.02 | H34: =SUM(H2:H33) -> 0 | I34: =SUM(I2:I33) -> 156.63 | ... U34: =SUM(U2:U33) -> 5 | X34: =SUM(X2:X33) -> 4279.15
A35: Total : | B35: =B34-(C34+D34+E34+F34+G34+H34+I34+J34+K34+L34+M34+N34+O34+P34+Q34+R34+S34+T34+U34) -> 5576.13 | D35: =D34+E34 -> 2118 | F35: =G34+F34 -> 665.92 | J35: >500 | K35: 400-499.99 | L35: 300-399.99 | M35: 200-299.99 | N35: 100-199.99 | O35: 0-99.99 | W35: Notes: | AA35: =(5000-(B35))/countif(B2:B32,"") -> #DIV/0! | AB35: =B35/B34 -> 0.56580128

Sheet Aug
A1: Date | B1: Earning | C1: Insuran | D1: Minyak | F1: Makan | H1: Oil Filter | I1: TnG | J1: Maintenance | K1: Grocery | L1: Online Shop | M1: Hair Cut | N1: Subscription | O1: Charity | P1: Phone Bil | Q1: Laundry | R1: Rent | S1: Bil E&W | T1: Parent | U1: Other | V1: Job | W1: Remarks | X1: Total Spend | Y1: Weekly Earning | Z1: Weekly Spend | AA1: Net Daily | AB1: Net Weekly | AC1: Cummulative
A2: 45870 | B2: 476.1 | C2: 7 | D2: 55 | F2: =6.8+2 -> 8.8 | N2: 15.9 | V2: 36 | X2: =sum(C2:U2) -> 86.7 | AA2: =B2-X2 -> 389.4 | AC2: =AA2 -> 389.4
A3: 45871 | B3: 261.6 | C3: 7 | D3: 55 | F3: 6.5 | I3: 5 | K3: 6.8 | T3: 200 | V3: 21 | X3: =sum(C3:U3) -> 280.3 | AA3: =B3-X3 -> -18.7 | AC3: =AC2+AA3 -> 370.7
A4: 45872 | B4: 272 | C4: 7 | D4: 55 | F4: 15.5 | K4: =10.9+6.6 -> 17.5 | V4: 23 | X4: =sum(C4:U4) -> 95 | Y4: =sum(B2:B4) -> 1009.7 | Z4: =sum(X2:X4) -> 462 | AA4: =B4-X4 -> 177 | AB4: =Y4-Z4 -> 547.7 | AC4: =AC3+AA4 -> 547.7
A5: 45873 | B5: 432.93 | C5: 7 | D5: 65 | F5: 8 | H5: 220 | R5: 350 | S5: 12.24 | V5: 23 | W5: AB 1st warning | X5: =sum(C5:U5) -> 662.24 | AA5: =B5-X5 -> -229.31 | AC5: =AC4+AA5 -> 318.39
A6: 45874 | B6: 216.8 | C6: 7 | D6: 65 | F6: 7 | G6: 14 | I6: 2.46 | K6: 6.35 | V6: 15 | X6: =sum(C6:U6) -> 101.81 | AA6: =B6-X6 -> 114.99 | AC6: =AC5+AA6 -> 433.38
A7: 45875 | B7: 203.2 | C7: 7 | D7: 60 | F7: 22.66 | G7: =12.6+3 -> 15.6 | O7: 2 | V7: 26 | W7: Ahmad's Cyberjaya | X7: =sum(C7:U7) -> 107.26 | AA7: =B7-X7 -> 95.94 | AC7: =AC6+AA7 -> 529.32
A8: 45876 | B8: 396.4 | C8: 7 | D8: 63 | E8: 55 | F8: 12.79 | G8: 16.5 | I8: 3.5 | V8: 31 | X8: =sum(C8:U8) -> 157.79 | AA8: =B8-X8 -> 238.61 | AC8: =AC7+AA8 -> 767.93
A9: 45877 | B9: 442.3 | C9: 7 | D9: 55 | E9: 50 | F9: 8.5 | I9: 3.5 | V9: 29 | X9: =sum(C9:U9) -> 124 | AA9: =B9-X9 -> 318.3 | AC9: =AC8+AA9 -> 1086.23
A10: 45878 | B10: 232 | C10: 7 | D10: 65 | F10: 8.9 | I10: 3.5 | V10: 19 | X10: =sum(C10:U10) -> 84.4 | AA10: =B10-X10 -> 147.6 | AC10: =AC9+AA10 -> 1233.83 | AD10: 1560
A11: 45879 | B11: 422.8 | C11: 7 | D11: 60 | F11: 17.5 | G11: 12 | V11: 34 | X11: =sum(C11:U11) -> 96.5 | Y11: =sum(B5:B11) -> 2346.43 | Z11: =sum(X5:X11) -> 1334 | AA11: =B11-X11 -> 326.3 | AB11: =Y11-Z11 -> 1012.43 | AC11: =AC10+AA11 -> 1560.13
A12: 45880 | B12: 629.17 | C12: 7 | D12: 65 | F12: 8 | I12: 4.59 | K12: 6.9 | V12: 18 | X12: =sum(C12:U12) -> 91.49 | AA12: =B12-X12 -> 537.68 | AC12: =AC11+AA12 -> 2097.81
A13: 45881 | B13: 200 | C13: 7 | D13: 65 | F13: 51.8 | V13: 18 | W13: omarpalace | X13: =sum(C13:U13) -> 123.8 | AA13: =B13-X13 -> 76.2 | AC13: =AC12+AA13 -> 2174.01
A14: 45882 | B14: 204 | C14: 7 | D14: 65 | F14: 53 | G14: 38.3 | I14: 3.85 | K14: 5.7 | V14: 20 | X14: =sum(C14:U14) -> 172.85 | AA14: =B14-X14 -> 31.15 | AC14: =AC13+AA14 -> 2205.16
A15: 45883 | B15: 304.1 | C15: 7 | F15: 12 | G15: 11.4 | I15: 2.46 | K15: 7.65 | V15: 20 | X15: =sum(C15:U15) -> 40.51 | AA15: =B15-X15 -> 263.59 | AC15: =AC14+AA15 -> 2468.75
A16: 45884 | B16: 213.7 | C16: 7 | D16: 55 | F16: 11.5 | G16: =5+4+12.5+3 -> 24.5 | I16: 5.46 | V16: 14 | X16: =sum(C16:U16) -> 103.46 | AA16: =B16-X16 -> 110.24 | AC16: =AC15+AA16 -> 2578.99
A17: 45885 | B17: 366.4 | C17: 7 | F17: 5.6 | G17: 11.5 | O17: 11 | V17: 30 | X17: =sum(C17:U17) -> 35.1 | AA17: =B17-X17 -> 331.3 | AC17: =AC16+AA17 -> 2910.29
A18: 45886 | B18: 369.6 | C18: 7 | D18: 65 | E18: 68 | F18: 15.4 | I18: =3.2+2+11.5 -> 16.7 | K18: 10.5 | V18: 27 | X18: =sum(C18:U18) -> 182.6 | Y18: =sum(B12:B18) -> 2286.97 | Z18: =sum(X12:X18) -> 749.81 | AA18: =B18-X18 -> 187 | AB18: =Y18-Z18 -> 1537.16 | AC18: =AC17+AA18 -> 3097.29
A19: 45887 | B19: 389.35 | C19: 7 | F19: 15.4 | K19: =U192 | U19: =20+15.5 -> 35.5 | V19: 15 | W19: hammer, towing | X19: =sum(C19:U19) -> 57.9 | AA19: =B19-X19 -> 331.45 | AC19: =AC18+AA19 -> 3428.74
A20: 45888 | B20: 216.7 | C20: 7 | D20: 60 | E20: 55 | F20: 11.1 | K20: =4.95 -> 4.95 | U20: =39+23.1 -> 62.1 | V20: 16 | W20: canvas | X20: =sum(C20:U20) -> 200.15 | AA20: =B20-X20 -> 16.55 | AC20: =AC19+AA20 -> 3445.29
A21: 45889 | B21: 204.1 | C21: 7 | F21: 13.5 | I21: =2.1+3.5 -> 5.6 | O21: 1 | P21: 50 | U21: 20 | V21: 21 | W21: racun anai² | X21: =sum(C21:U21) -> 97.1 | AA21: =B21-X21 -> 107 | AC21: =AC20+AA21 -> 3552.29
A22: 45890 | B22: 248.8 | C22: 7 | D22: 68 | F22: 13.4 | I22: 3.2 | U22: 1 | V22: 18 | X22: =sum(C22:U22) -> 92.6 | AA22: =B22-X22 -> 156.2 | AC22: =AC21+AA22 -> 3708.49 | AD22: 1580
A23: 45891 | B23: 200.8 | C23: 7 | D23: 65 | F23: 9.8 | G23: =12+2 -> 14 | I23: 0.98 | O23: 1 | V23: 24 | X23: =sum(C23:U23) -> 97.78 | AA23: =B23-X23 -> 103.02 | AC23: =AC22+AA23 -> 3811.51
A24: 45892 | B24: 256 | C24: 7 | D24: 55 | F24: 14.5 | J24: =120+190 -> 310 | K24: 14 | V24: 19 | W24: brake pad (belakang), spark plug | X24: =sum(C24:U24) -> 400.5 | AA24: =B24-X24 -> -144.5 | AC24: =AC23+AA24 -> 3667.01
A25: 45893 | B25: 217.6 | C25: 7 | D25: 55 | F25: 15 | K25: 6 | V25: 14 | X25: =sum(C25:U25) -> 83 | Y25: =sum(B19:B25) -> 1733.35 | Z25: =sum(X19:X25) -> 1029.03 | AA25: =B25-X25 -> 134.6 | AB25: =Y25-Z25 -> 704.32 | AC25: =AC24+AA25 -> 3801.61
A26: 45894 | B26: 553.46 | C26: 7 | D26: 55 | E26: 65 | F26: 11.8 | I26: =2.1+1 -> 3.1 | O26: 1 | V26: 34 | X26: =sum(C26:U26) -> 142.9 | AA26: =B26-X26 -> 410.56 | AC26: =AC25+AA26 -> 4212.17
A27: 45895 | B27: 230.2 | C27: 7 | D27: 60 | F27: 13.5 | G27: 11 | I27: 2.1 | K27: 6.8 | V27: 22 | X27: =sum(C27:U27) -> 100.4 | AA27: =B27-X27 -> 129.8 | AC27: =AC26+AA27 -> 4341.97
A28: 45896 | B28: 376.8 | C28: 7 | D28: 60 | F28: 10.3 | I28: =3.2+3.5+3.85+3.2+2.1 -> 15.85 | V28: 26 | X28: =sum(C28:U28) -> 93.15 | AA28: =B28-X28 -> 283.65 | AC28: =AC27+AA28 -> 4625.62
A29: 45897 | B29: 320.7 | C29: 7 | D29: 60 | F29: =12.1+9 -> 21.1 | G29: 11.5 | I29: 2.1 | Q29: 12 | V29: 25 | X29: =sum(C29:U29) -> 113.7 | AA29: =B29-X29 -> 207 | AC29: =AC28+AA29 -> 4832.62
A30: 45898 | B30: 222.5 | C30: 7 | D30: 55 | F30: 7.5 | G30: 18 | I30: 2.1 | K30: 7.5 | V30: 15 | X30: =sum(C30:U30) -> 97.1 | AA30: =B30-X30 -> 125.4 | AC30: =AC29+AA30 -> 4958.02
A31: 45899 | B31: 352.9 | C31: 7 | D31: 55 | F31: =14+7.7 -> 21.7 | G31: 8 | V31: 25 | X31: =sum(C31:U31) -> 91.7 | AA31: =B31-X31 -> 261.2 | AC31: =AC30+AA31 -> 5219.22
A32: 45900 | B32: 468.5 | C32: 7 | D32: 55 | E32: 50 | I32: =3.51+3.85+6.07 -> 13.43 | U32: 557.06 | V32: 30 | W32: Infinix hot 60 5g+ | X32: =sum(C32:U32) -> 682.49 | Y32: =sum(B26:B32) -> 2525.06 | Z32: =sum(X26:X32) -> 1321.44 | AA32: =B32-X32 -> -213.99 | AB32: =Y32-Z32 -> 1203.62 | AC32: =AC31+AA32 -> 5005.23
A34: =count(B2:B32,"number")&" "&"/"&" "&countif(B2:B32,"") -> 31 / 0 | B34: =SUM(B2:B33) -> 9901.51 | C34: =SUM(C2:C33) -> 217 | D34: =SUM(D2:D33) -> 1616 | E34: =SUM(E2:E33) -> 343 | F34: =SUM(F2:F33) -> 452.05 | G34: =SUM(G2:G33) -> 206.3 | H34: =SUM(H2:H33) -> 220 | I34: =SUM(I2:I33) -> 99.48 | ... U34: =SUM(U2:U33) -> 675.66 | X34: =SUM(X2:X33) -> 4896.28
A35: Total : | B35: =B34-(C34+D34+E34+F34+G34+H34+I34+J34+K34+L34+M34+N34+O34+P34+Q34+R34+S34+T34+U34) -> 5005.23 | D35: =D34+E34 -> 1959 | F35: =G34+F34 -> 658.35 | J35: >500 | K35: 400-499.99 | L35: 300-399.99 | M35: 200-299.99 | N35: 100-199.99 | O35: 0-99.99 | W35: Notes: | AA35: =(5000-(B35))/countif(B2:B32,"") -> #DIV/0! | AB35: =B35/B34 -> 0.50550169

Sheet Sep
A1: Date | B1: Earning | C1: Insuran | D1: Minyak | F1: Makan | H1: Oil Filter | I1: TnG | J1: Maintenance | K1: Grocery | L1: Online Shop | M1: Hair Cut | N1: Subscription | O1: Charity | P1: Phone Bil | Q1: Laundry | R1: Rent | S1: Bil E&W | T1: Parent | U1: Other | V1: Job | W1: Remarks | X1: Total Spend | Y1: Weekly Earning | Z1: Weekly Spend | AA1: Net Daily | AB1: Net Weekly | AC1: Cummulative | AD1: Deposit
A2: 45901 | B2: 400.6 | C2: 7 | F2: =7.5+6 -> 13.5 | K2: 11.8 | R2: 350 | T2: 200 | U2: 100 | V2: 28 | W2: Business Structure | X2: =sum(C2:U2) -> 682.3 | AA2: =B2-X2 -> -281.7 | AC2: =AA2 -> -281.7
A3: 45902 | B3: 605.63 | C3: 7 | D3: 65 | F3: =7 -> 7 | G3: 5.1 | I3: =1.56+2+3.85 -> 7.41 | S3: 11.51 | V3: 15 | X3: =sum(C3:U3) -> 103.02 | AA3: =B3-X3 -> 502.61 | AC3: =AC2+AA3 -> 220.91
A4: 45903 | B4: 211.3 | C4: 7 | D4: 60 | F4: =11.9+1.5 -> 13.4 | G4: =9+3+8 -> 20 | I4: =3.2+3.5 -> 6.7 | O4: 10 | V4: 20 | X4: =sum(C4:U4) -> 117.1 | AA4: =B4-X4 -> 94.2 | AC4: =AC3+AA4 -> 315.11
A5: 45904 | B5: 262.4 | C5: 7 | D5: 65 | F5: =7+24 -> 31 | G5: 93.5 | K5: =8.2+29.5 -> 37.7 | V5: 20 | X5: =sum(C5:U5) -> 234.2 | AA5: =B5-X5 -> 28.2 | AC5: =AC4+AA5 -> 343.31
A6: 45905 | B6: 226.4 | C6: 7 | D6: 55 | F6: =4+10+2.6 -> 16.6 | I6: 5.5 | V6: 26 | X6: =sum(C6:U6) -> 84.1 | AA6: =B6-X6 -> 142.3 | AC6: =AC5+AA6 -> 485.61
A7: 45906 | B7: 348 | C7: 7 | D7: 55 | F7: 14.7 | I7: 3.2 | K7: 6.2 | V7: 27 | X7: =sum(C7:U7) -> 86.1 | AA7: =B7-X7 -> 261.9 | AC7: =AC6+AA7 -> 747.51
A8: 45907 | B8: 263.8 | C8: 7 | D8: 60 | E8: 50 | F8: 12.5 | G8: 14.4 | I8: 4.51 | K8: 8.8 | Q8: 12 | V8: 21 | X8: =sum(C8:U8) -> 169.21 | Y8: =sum(B2:B8) -> 2318.13 | Z8: =sum(X2:X8) -> 1476.03 | AA8: =B8-X8 -> 94.59 | AB8: =Y8-Z8 -> 842.1 | AC8: =AC7+AA8 -> 842.1
A9: 45908 | B9: 602.88 | C9: 7 | D9: 65 | F9: 14 | G9: 10 | I9: 3.5 | K9: =10.2+6.4 -> 16.6 | V9: 18 | X9: =sum(C9:U9) -> 116.1 | AA9: =B9-X9 -> 486.78 | AC9: =AC8+AA9 -> 1328.88
A10: 45909 | B10: 272 | C10: 7 | D10: 70 | F10: 11.5 | G10: =11.5+9 -> 20.5 | I10: =0.85+0.85+3.2 -> 4.9 | V10: 22 | X10: =sum(C10:U10) -> 113.9 | AA10: =B10-X10 -> 158.1 | AC10: =AC9+AA10 -> 1486.98
A11: 45910 | B11: 286.4 | C11: 7 | D11: 55 | F11: 7.8 | I11: =3.2 -> 3.2 | K11: =5.5+8.1 -> 13.6 | V11: 20 | X11: =sum(C11:U11) -> 86.6 | AA11: =B11-X11 -> 199.8 | AC11: =AC10+AA11 -> 1686.78 | AD11: 2310
A12: 45911 | B12: 298.4 | C12: 7 | F12: 13.4 | G12: =11.5+8 -> 19.5 | I12: =3.61 -> 3.61 | V12: 25 | X12: =sum(C12:U12) -> 43.51 | AA12: =B12-X12 -> 254.89 | AC12: =AC11+AA12 -> 1941.67
A13: 45912 | B13: 242.4 | C13: 7 | D13: 65 | E13: 60 | F13: 14.1 | G13: =12.5+15 -> 27.5 | I13: 9 | U13: 180 | V13: 13 | X13: =sum(C13:U13) -> 362.6 | AA13: =B13-X13 -> -120.2 | AC13: =AC12+AA13 -> 1821.47
A14: 45913 | B14: 200 | C14: 7 | U14: 9.9 | V14: 8 | X14: =sum(C14:U14) -> 16.9 | AA14: =B14-X14 -> 183.1 | AC14: =AC13+AA14 -> 2004.57
A15: 45914 | B15: 204 | C15: 7 | D15: 65 | I15: =5 -> 5 | U15: =10+3.5 -> 13.5 | V15: 17 | X15: =sum(C15:U15) -> 90.5 | Y15: =sum(B9:B15) -> 2106.08 | Z15: =sum(X9:X15) -> 830.11 | AA15: =B15-X15 -> 113.5 | AB15: =Y15-Z15 -> 1275.97 | AC15: =AC14+AA15 -> 2118.07
A16: 45915 | B16: 349.68 | C16: 7 | D16: 65 | F16: =10.5+4 -> 14.5 | I16: =1.72 -> 1.72 | P16: 50 | V16: 16 | X16: =sum(C16:U16) -> 138.22 | AA16: =B16-X16 -> 211.46 | AC16: =AC15+AA16 -> 2329.53
A17: 45916 | B17: 215 | C17: 7 | D17: 50 | F17: 7.5 | G17: 16.8 | I17: =2.1+3.2 -> 5.3 | U17: 3000 | V17: 19 | W17: repair myvi | X17: =sum(C17:U17) -> 3086.6 | AA17: =B17-X17 -> -2871.6 | AC17: =AC16+AA17 -> -542.07
A18: 45917 | B18: 314.2 | C18: 7 | D18: 65 | F18: 11.5 | G18: 23 | V18: 24 | X18: =sum(C18:U18) -> 106.5 | AA18: =B18-X18 -> 207.7 | AC18: =AC17+AA18 -> -334.37
A19: 45918 | B19: 352.2 | C19: 7 | D19: 60 | F19: 16 | I19: 5 | K19: 3 | V19: 25 | X19: =sum(C19:U19) -> 91 | AA19: =B19-X19 -> 261.2 | AC19: =AC18+AA19 -> -73.17
A20: 45919 | B20: =346.2+25.8 -> 372 | C20: 7 | D20: 50 | F20: 106 | K20: 12.13 | V20: 24 | X20: =sum(C20:U20) -> 175.13 | AA20: =B20-X20 -> 196.87 | AC20: =AC19+AA20 -> 123.7
A21: 45920 | B21: 267.2 | C21: 7 | D21: 68 | F21: 9 | G21: 12.7 | I21: =3.2+4.5+1.72 -> 9.42 | V21: 19 | W21: visit myvi | X21: =sum(C21:U21) -> 106.12 | AA21: =B21-X21 -> 161.08 | AC21: =AC20+AA21 -> 284.78
A22: 45921 | B22: 328.8 | C22: 7 | D22: 55 | F22: 14.9 | G22: 10 | I22: =3.12+2.9+3.03+1 -> 10.05 | K22: 10 | V22: 27 | X22: =sum(C22:U22) -> 106.95 | Y22: =sum(B16:B22) -> 2199.08 | Z22: =sum(X16:X22) -> 3810.52 | AA22: =B22-X22 -> 221.85 | AB22: =Y22-Z22 -> -1611.44 | AC22: =AC21+AA22 -> 506.63
A23: 45922 | B23: =275.2+206.26+2 -> 483.46 | C23: 7 | D23: 60 | F23: 6 | G23: 12 | V23: 22 | X23: =sum(C23:U23) -> 85 | AA23: =B23-X23 -> 398.46 | AC23: =AC22+AA23 -> 905.09
A24: 45923 | B24: 233.5 | C24: 7 | D24: 55 | F24: 9.5 | I24: =3.2+2+4.43 -> 9.63 | K24: 8.5 | V24: 32 | X24: =sum(C24:U24) -> 89.63 | AA24: =B24-X24 -> 143.87 | AC24: =AC23+AA24 -> 1048.96
A25: 45924 | B25: 304 | C25: 7 | D25: 65 | F25: =7+7 -> 14 | G25: 13.9 | I25: =2.5+6.89 -> 9.39 | V25: 25 | X25: =sum(C25:U25) -> 109.29 | AA25: =B25-X25 -> 194.71 | AC25: =AC24+AA25 -> 1243.67
A26: 45925 | B26: 233 | C26: 7 | F26: =8.4+10 -> 18.4 | G26: 13 | I26: 2.71 | V26: 19 | X26: =sum(C26:U26) -> 41.11 | AA26: =B26-X26 -> 191.89 | AC26: =AC25+AA26 -> 1435.56
A27: 45926 | B27: 298.5 | C27: 7 | D27: 65 | F27: 5.2 | G27: 15.5 | I27: 4.51 | V27: 23 | W27: 1 star | X27: =sum(C27:U27) -> 97.21 | AA27: =B27-X27 -> 201.29 | AC27: =AC26+AA27 -> 1636.85
A28: 45927 | B28: 216 | C28: 7 | D28: 65 | F28: 7.9 | I28: =1.5+2.54 -> 4.04 | K28: 16.8 | U28: 1865 | V28: 17 | W28: ambil kereta myvi | X28: =sum(C28:U28) -> 1965.74 | AA28: =B28-X28 -> -1749.74 | AC28: =AC27+AA28 -> -112.89
